Workbook

Sheet Aannames
A1: AANNAMES — vul hier alle bedragen in
A2: Gele cellen = zelf invullen. Alle andere sheets rekenen hierop door.
A4: STARTKAPITAAL
A5: Startkapitaal (EUR) | C5: Beginbedrag op de rekening
A7: BATTERIJSYSTEMEN (ESS)
A8: Verkoopprijs per systeem (EUR) | C8: Gemiddelde verkoopprijs
A9: Inkoopprijs per systeem (EUR) | C9: Inkoopkosten per eenheid
A11: AC LAADPALEN
A12: Verkoopprijs per AC lader (EUR) | C12: Gemiddelde verkoopprijs
A13: Inkoopprijs per AC lader (EUR) | C13: Inkoopkosten per eenheid
A15: DC SNELLADERS
A16: Verkoopprijs per DC snellader (EUR) | C16: Gemiddelde verkoopprijs
A17: Inkoopprijs per DC snellader (EUR) | C17: Inkoopkosten per eenheid
A19: LAADOPBRENGST
A20: Marge per kWh (EUR) | C20: Verkoopprijs minus inkoopprijs per kWh
A21: Gem. kWh per laadpaal per maand | C21: Gemiddeld verbruik per laadpunt
A23: SUPPORT EN ONDERHOUD
A24: Support fee per klant per maand (EUR) | C24: Terugkerende maandelijkse fee
A26: KICKBACK ZONNEPANELEN
A27: Commissiepercentage (%) | C27: Percentage van installatiewaarde
A28: Gem. installatiewaarde (EUR) | C28: Gemiddelde zonne-installatie
A30: EXTRA GARANTIE
A31: Garantieprijs per systeem (EUR) | C31: Prijs extended warranty
A32: Take-rate garantie (%) | C32: Percentage klanten dat garantie neemt
A34: OVERIGE KOSTEN (startbedrag per maand)
A35: Personeel (EUR/maand, jaar 1) | C35: Vul per maand aan in Budget-sheet
A36: Marketing en sales (EUR/maand, jaar 1) | C36: Vul per maand aan in Budget-sheet
A37: Kantoor en operations (EUR/maand) | C37: Vul per maand aan in Budget-sheet
A38: Software, tools en IT (EUR/maand) | C38: Vul per maand aan in Budget-sheet
A39: Verzekeringen (EUR/maand) | C39: Vul per maand aan in Budget-sheet
A41: PERCENTAGES
A42: Onderdelen (% van hardware-omzet) | B42: 0.03 | C42: Reserve voor vervangende onderdelen
A43: Installatie (% van hardware-omzet) | B43: 0.12 | C43: Installatie- en logistieke kosten
A44: Onvoorzien (% van totale kosten) | B44: 0.05 | C44: Buffer voor onverwachte uitgaven
A45: BTW tarief | B45: 0.21 | C45: Nederlands BTW-tarief

Sheet Kosten
A1: KOSTENSPECIFICATIE
A2: Vul alle kosten in. Budget-sheet rekent hier automatisch op door.
A4: INKOOP HARDWARE (kostprijs per eenheid)
A5: Kostenpost | B5: Type | C5: Bedrag | D5: Toelichting
A6: Inkoopprijs batterijsysteem | B6: per stuk | C6: 0 | D6: Per ESS-systeem
A7: Inkoopprijs AC laadpaal | B7: per stuk | C7: 0 | D7: Per laadpaal
A8: Inkoopprijs DC snellader | B8: per stuk | C8: 0 | D8: Per snellader
C9: 0
A10: INSTALLATIE EN LOGISTIEK
A11: Kostenpost | B11: Type | C11: Bedrag | D11: Toelichting
A12: Installatie batterijsysteem | B12: per stuk | C12: 0 | D12: Per systeem
A13: Installatie AC lader | B13: per stuk | C13: 0 | D13: Per laadpaal
A14: Installatie DC snellader | B14: per stuk | C14: 0 | D14: Per snellader
A15: Transport en logistiek per maand | B15: maandelijks | C15: 0 | D15: Vaste transportkosten
C16: 0
A17: PERSONEEL
A18: Kostenpost | B18: Type | C18: Bedrag | D18: Toelichting
A19: Salarissen jaar 1 (EUR/maand) | B19: maandelijks | C19: 0 | D19: Bruto salarissen alle FTE
A20: Salarissen jaar 2 (EUR/maand) | B20: maandelijks | C20: 0 | D20: Opgeschaald in jaar 2
A21: Salarissen jaar 3 (EUR/maand) | B21: maandelijks | C21: 0 | D21: Opgeschaald in jaar 3
A22: Werkgeverslasten (%) | B22: pct_sal | C22: 0.3 | D22: Percentage bovenop salaris
A23: Freelancers en extern | B23: maandelijks | C23: 0 | D23: Indien van toepassing
C24: 0
A25: MARKETING EN SALES
A26: Kostenpost | B26: Type | C26: Bedrag | D26: Toelichting
A27: Online marketing | B27: maandelijks | C27: 0 | D27: Google Ads, LinkedIn, etc.
A28: Content en social media | B28: maandelijks | C28: 0 | D28: Content creatie
A29: Beurzen en events | B29: maandelijks | C29: 0 | D29: Vakbeurzen, netwerkevents
A30: Sales commissie (% van omzet) | B30: pct_rev | C30: 0 | D30: Commissie sales team
A31: Drukwerk en promotie | B31: maandelijks | C31: 0 | D31: Brochures, relatiegeschenken
C32: 0
A33: KANTOOR EN OPERATIONS
A34: Kostenpost | B34: Type | C34: Bedrag | D34: Toelichting
A35: Huur kantoorruimte | B35: maandelijks | C35: 0 | D35: Inclusief servicekosten
A36: Kantoormateriaal | B36: maandelijks | C36: 0 | D36: Verbruik, printers
A37: Telecom en internet | B37: maandelijks | C37: 0 | D37: Telefoon, cloud
A38: Reiskosten | B38: maandelijks | C38: 0 | D38: Kilometervergoeding, OV
C39: 0
A40: SOFTWARE, TOOLS EN IT
A41: Kostenpost | B41: Type | C41: Bedrag | D41: Toelichting
...

Sheet Verkoopprognose
A1: VERKOOPPROGNOSE 2026-2029
A2: Vul aantallen per maand in (gele cellen). Prijzen komen uit Aannames.
A4: 1. BATTERIJSYSTEMEN (ESS)
A5: # | B5: Maand | C5: Aantal | D5: Prijs per stuk | E5: Totaal
A6: 1 | B6: Aug '26 | D6: =Aannames!B8 | E6: =IF(C6="","",C6*D6)
A7: 2 | B7: Sep '26 | D7: =Aannames!B8 | E7: =IF(C7="","",C7*D7)
A8: 3 | B8: Okt '26 | D8: =Aannames!B8 | E8: =IF(C8="","",C8*D8)
A9: 4 | B9: Nov '26 | D9: =Aannames!B8 | E9: =IF(C9="","",C9*D9)
A10: 5 | B10: Dec '26 | D10: =Aannames!B8 | E10: =IF(C10="","",C10*D10)
A11: 6 | B11: Jan '27 | D11: =Aannames!B8 | E11: =IF(C11="","",C11*D11)
A12: 7 | B12: Feb '27 | D12: =Aannames!B8 | E12: =IF(C12="","",C12*D12)
A13: 8 | B13: Mrt '27 | D13: =Aannames!B8 | E13: =IF(C13="","",C13*D13)
A14: 9 | B14: Apr '27 | D14: =Aannames!B8 | E14: =IF(C14="","",C14*D14)
A15: 10 | B15: Mei '27 | D15: =Aannames!B8 | E15: =IF(C15="","",C15*D15)
A16: 11 | B16: Jun '27 | D16: =Aannames!B8 | E16: =IF(C16="","",C16*D16)
A17: 12 | B17: Jul '27 | D17: =Aannames!B8 | E17: =IF(C17="","",C17*D17)
A18: 13 | B18: Aug '27 | D18: =Aannames!B8 | E18: =IF(C18="","",C18*D18)
A19: 14 | B19: Sep '27 | D19: =Aannames!B8 | E19: =IF(C19="","",C19*D19)
A20: 15 | B20: Okt '27 | D20: =Aannames!B8 | E20: =IF(C20="","",C20*D20)
A21: 16 | B21: Nov '27 | D21: =Aannames!B8 | E21: =IF(C21="","",C21*D21)
A22: 17 | B22: Dec '27 | D22: =Aannames!B8 | E22: =IF(C22="","",C22*D22)
A23: 18 | B23: Jan '28 | D23: =Aannames!B8 | E23: =IF(C23="","",C23*D23)
A24: 19 | B24: Feb '28 | D24: =Aannames!B8 | E24: =IF(C24="","",C24*D24)
A25: 20 | B25: Mrt '28 | D25: =Aannames!B8 | E25: =IF(C25="","",C25*D25)
A26: 21 | B26: Apr '28 | D26: =Aannames!B8 | E26: =IF(C26="","",C26*D26)
A27: 22 | B27: Mei '28 | D27: =Aannames!B8 | E27: =IF(C27="","",C27*D27)
A28: 23 | B28: Jun '28 | D28: =Aannames!B8 | E28: =IF(C28="","",C28*D28)
A29: 24 | B29: Jul '28 | D29: =Aannames!B8 | E29: =IF(C29="","",C29*D29)
A30: 25 | B30: Aug '28 | D30: =Aannames!B8 | E30: =IF(C30="","",C30*D30)
A31: 26 | B31: Sep '28 | D31: =Aannames!B8 | E31: =IF(C31="","",C31*D31)
A32: 27 | B32: Okt '28 | D32: =Aannames!B8 | E32: =IF(C32="","",C32*D32)
A33: 28 | B33: Nov '28 | D33: =Aannames!B8 | E33: =IF(C33="","",C33*D33)
A34: 29 | B34: Dec '28 | D34: =Aannames!B8 | E34: =IF(C34="","",C34*D34)
A35: 30 | B35: Jan '29 | D35: =Aannames!B8 | E35: =IF(C35="","",C35*D35)
A36: 31 | B36: Feb '29 | D36: =Aannames!B8 | E36: =IF(C36="","",C36*D36)
A37: 32 | B37: Mrt '29 | D37: =Aannames!B8 | E37: =IF(C37="","",C37*D37)
A38: 33 | B38: Apr '29 | D38: =Aannames!B8 | E38: =IF(C38="","",C38*D38)
A39: 34 | B39: Mei '29 | D39: =Aannames!B8 | E39: =IF(C39="","",C39*D39)
A40: 35 | B40: Jun '29 | D40: =Aannames!B8 | E40: =IF(C40="","",C40*D40)
A41: 36 | B41: Jul '29 | D41: =Aannames!B8 | E41: =IF(C41="","",C41*D41)
...

Sheet Budget
A1: HES Budget 2026-2029
B3: Aug '26 | C3: Sep '26 | D3: Okt '26 | E3: Nov '26 | F3: Dec '26 | G3: Jan '27 | H3: Feb '27 | I3: Mrt '27 | J3: Apr '27 | K3: Mei '27 | L3: Jun '27 | M3: Jul '27 | N3: Aug '27 | O3: Sep '27 | P3: Okt '27 | Q3: Nov '27 | R3: Dec '27 | S3: Jan '28 | T3: Feb '28 | U3: Mrt '28 | V3: Apr '28 | W3: Mei '28 | X3: Jun '28 | Y3: Jul '28 | Z3: Aug '28 | AA3: Sep '28 | AB3: Okt '28 | AC3: Nov '28 | AD3: Dec '28 | AE3: Jan '29 | AF3: Feb '29 | AG3: Mrt '29 | AH3: Apr '29 | AI3: Mei '29 | AJ3: Jun '29 | AK3: Jul '29
A4: OMZET
A5: Batterijsystemen (ESS) | B5: =IFERROR('Verkoopprognose'!E6,0) | C5: =IFERROR('Verkoopprognose'!E7,0) | D5: =IFERROR('Verkoopprognose'!E8,0) | E5: =IFERROR('Verkoopprognose'!E9,0) | F5: =IFERROR('Verkoopprognose'!E10,0) | G5: =IFERROR('Verkoopprognose'!E11,0) | H5: =IFERROR('Verkoopprognose'!E12,0) | I5: =IFERROR('Verkoopprognose'!E13,0) | J5: =IFERROR('Verkoopprognose'!E14,0) | K5: =IFERROR('Verkoopprognose'!E15,0) | L5: =IFERROR('Verkoopprognose'!E16,0) | M5: =IFERROR('Verkoopprognose'!E17,0) | N5: =IFERROR('Verkoopprognose'!E18,0) | O5: =IFERROR('Verkoopprognose'!E19,0) | P5: =IFERROR('Verkoopprognose'!E20,0) | Q5: =IFERROR('Verkoopprognose'!E21,0) | R5: =IFERROR('Verkoopprognose'!E22,0) | S5: =IFERROR('Verkoopprognose'!E23,0) | T5: =IFERROR('Verkoopprognose'!E24,0) | U5: =IFERROR('Verkoopprognose'!E25,0) | V5: =IFERROR('Verkoopprognose'!E26,0) | W5: =IFERROR('Verkoopprognose'!E27,0) | X5: =IFERROR('Verkoopprognose'!E28,0) | Y5: =IFERROR('Verkoopprognose'!E29,0) | Z5: =IFERROR('Verkoopprognose'!E30,0) | AA5: =IFERROR('Verkoopprognose'!E31,0) | AB5: =IFERROR('Verkoopprognose'!E32,0) | AC5: =IFERROR('Verkoopprognose'!E33,0) | AD5: =IFERROR('Verkoopprognose'!E34,0) | AE5: =IFERROR('Verkoopprognose'!E35,0) | AF5: =IFERROR('Verkoopprognose'!E36,0) | AG5: =IFERROR('Verkoopprognose'!E37,0) | AH5: =IFERROR('Verkoopprognose'!E38,0) | AI5: =IFERROR('Verkoopprognose'!E39,0) | AJ5: =IFERROR('Verkoopprognose'!E40,0) | AK5: =IFERROR('Verkoopprognose'!E41,0)
A6: AC Laadpalen | B6: =IFERROR('Verkoopprognose'!E46,0) | C6: =IFERROR('Verkoopprognose'!E47,0) | D6: =IFERROR('Verkoopprognose'!E48,0) | E6: =IFERROR('Verkoopprognose'!E49,0) | F6: =IFERROR('Verkoopprognose'!E50,0) | G6: =IFERROR('Verkoopprognose'!E51,0) | H6: =IFERROR('Verkoopprognose'!E52,0) | I6: =IFERROR('Verkoopprognose'!E53,0) | J6: =IFERROR('Verkoopprognose'!E54,0) | K6: =IFERROR('Verkoopprognose'!E55,0) | L6: =IFERROR('Verkoopprognose'!E56,0) | M6: =IFERROR('Verkoopprognose'!E57,0) | N6: =IFERROR('Verkoopprognose'!E58,0) | O6: =IFERROR('Verkoopprognose'!E59,0) | P6: =IFERROR('Verkoopprognose'!E60,0) | Q6: =IFERROR('Verkoopprognose'!E61,0) | R6: =IFERROR('Verkoopprognose'!E62,0) | S6: =IFERROR('Verkoopprognose'!E63,0) | T6: =IFERROR('Verkoopprognose'!E64,0) | U6: =IFERROR('Verkoopprognose'!E65,0) | V6: =IFERROR('Verkoopprognose'!E66,0) | W6: =IFERROR('Verkoopprognose'!E67,0) | X6: =IFERROR('Verkoopprognose'!E68,0) | Y6: =IFERROR('Verkoopprognose'!E69,0) | Z6: =IFERROR('Verkoopprognose'!E70,0) | AA6: =IFERROR('Verkoopprognose'!E71,0) | AB6: =IFERROR('Verkoopprognose'!E72,0) | AC6: =IFERROR('Verkoopprognose'!E73,0) | AD6: =IFERROR('Verkoopprognose'!E74,0) | AE6: =IFERROR('Verkoopprognose'!E75,0) | AF6: =IFERROR('Verkoopprognose'!E76,0) | AG6: =IFERROR('Verkoopprognose'!E77,0) | AH6: =IFERROR('Verkoopprognose'!E78,0) | AI6: =IFERROR('Verkoopprognose'!E79,0) | AJ6: =IFERROR('Verkoopprognose'!E80,0) | AK6: =IFERROR('Verkoopprognose'!E81,0)
A7: DC Snelladers | B7: =IFERROR('Verkoopprognose'!E86,0) | C7: =IFERROR('Verkoopprognose'!E87,0) | D7: =IFERROR('Verkoopprognose'!E88,0) | E7: =IFERROR('Verkoopprognose'!E89,0) | F7: =IFERROR('Verkoopprognose'!E90,0) | G7: =IFERROR('Verkoopprognose'!E91,0) | H7: =IFERROR('Verkoopprognose'!E92,0) | I7: =IFERROR('Verkoopprognose'!E93,0) | J7: =IFERROR('Verkoopprognose'!E94,0) | K7: =IFERROR('Verkoopprognose'!E95,0) | L7: =IFERROR('Verkoopprognose'!E96,0) | M7: =IFERROR('Verkoopprognose'!E97,0) | N7: =IFERROR('Verkoopprognose'!E98,0) | O7: =IFERROR('Verkoopprognose'!E99,0) | P7: =IFERROR('Verkoopprognose'!E100,0) | Q7: =IFERROR('Verkoopprognose'!E101,0) | R7: =IFERROR('Verkoopprognose'!E102,0) | S7: =IFERROR('Verkoopprognose'!E103,0) | T7: =IFERROR('Verkoopprognose'!E104,0) | U7: =IFERROR('Verkoopprognose'!E105,0) | V7: =IFERROR('Verkoopprognose'!E106,0) | W7: =IFERROR('Verkoopprognose'!E107,0) | X7: =IFERROR('Verkoopprognose'!E108,0) | Y7: =IFERROR('Verkoopprognose'!E109,0) | Z7: =IFERROR('Verkoopprognose'!E110,0) | AA7: =IFERROR('Verkoopprognose'!E111,0) | AB7: =IFERROR('Verkoopprognose'!E112,0) | AC7: =IFERROR('Verkoopprognose'!E113,0) | AD7: =IFERROR('Verkoopprognose'!E114,0) | AE7: =IFERROR('Verkoopprognose'!E115,0) | AF7: =IFERROR('Verkoopprognose'!E116,0) | AG7: =IFERROR('Verkoopprognose'!E117,0) | AH7: =IFERROR('Verkoopprognose'!E118,0) | AI7: =IFERROR('Verkoopprognose'!E119,0) | AJ7: =IFERROR('Verkoopprognose'!E120,0) | AK7: =IFERROR('Verkoopprognose'!E121,0)
A8: Laadopbrengst (EUR/kWh) | B8: =IFERROR((B6+B7)*Aannames!B20*Aannames!B21,0) | C8: =IFERROR((C6+C7)*Aannames!B20*Aannames!B21,0) | D8: =IFERROR((D6+D7)*Aannames!B20*Aannames!B21,0) | E8: =IFERROR((E6+E7)*Aannames!B20*Aannames!B21,0) | F8: =IFERROR((F6+F7)*Aannames!B20*Aannames!B21,0) | G8: =IFERROR((G6+G7)*Aannames!B20*Aannames!B21,0) | H8: =IFERROR((H6+H7)*Aannames!B20*Aannames!B21,0) | I8: =IFERROR((I6+I7)*Aannames!B20*Aannames!B21,0) | J8: =IFERROR((J6+J7)*Aannames!B20*Aannames!B21,0) | K8: =IFERROR((K6+K7)*Aannames!B20*Aannames!B21,0) | L8: =IFERROR((L6+L7)*Aannames!B20*Aannames!B21,0) | M8: =IFERROR((M6+M7)*Aannames!B20*Aannames!B21,0) | N8: =IFERROR((N6+N7)*Aannames!B20*Aannames!B21,0) | O8: =IFERROR((O6+O7)*Aannames!B20*Aannames!B21,0) | P8: =IFERROR((P6+P7)*Aannames!B20*Aannames!B21,0) | Q8: =IFERROR((Q6+Q7)*Aannames!B20*Aannames!B21,0) | R8: =IFERROR((R6+R7)*Aannames!B20*Aannames!B21,0) | S8: =IFERROR((S6+S7)*Aannames!B20*Aannames!B21,0) | T8: =IFERROR((T6+T7)*Aannames!B20*Aannames!B21,0) | U8: =IFERROR((U6+U7)*Aannames!B20*Aannames!B21,0) | V8: =IFERROR((V6+V7)*Aannames!B20*Aannames!B21,0) | W8: =IFERROR((W6+W7)*Aannames!B20*Aannames!B21,0) | X8: =IFERROR((X6+X7)*Aannames!B20*Aannames!B21,0) | Y8: =IFERROR((Y6+Y7)*Aannames!B20*Aannames!B21,0) | Z8: =IFERROR((Z6+Z7)*Aannames!B20*Aannames!B21,0) | AA8: =IFERROR((AA6+AA7)*Aannames!B20*Aannames!B21,0) | AB8: =IFERROR((AB6+AB7)*Aannames!B20*Aannames!B21,0) | AC8: =IFERROR((AC6+AC7)*Aannames!B20*Aannames!B21,0) | AD8: =IFERROR((AD6+AD7)*Aannames!B20*Aannames!B21,0) | AE8: =IFERROR((AE6+AE7)*Aannames!B20*Aannames!B21,0) | AF8: =IFERROR((AF6+AF7)*Aannames!B20*Aannames!B21,0) | AG8: =IFERROR((AG6+AG7)*Aannames!B20*Aannames!B21,0) | AH8: =IFERROR((AH6+AH7)*Aannames!B20*Aannames!B21,0) | AI8: =IFERROR((AI6+AI7)*Aannames!B20*Aannames!B21,0) | AJ8: =IFERROR((AJ6+AJ7)*Aannames!B20*Aannames!B21,0) | AK8: =IFERROR((AK6+AK7)*Aannames!B20*Aannames!B21,0)
A9: Support en onderhoud | B9: =IFERROR('Verkoopprognose'!C126*Aannames!B24,0) | C9: =IFERROR('Verkoopprognose'!C127*Aannames!B24,0) | D9: =IFERROR('Verkoopprognose'!C128*Aannames!B24,0) | E9: =IFERROR('Verkoopprognose'!C129*Aannames!B24,0) | F9: =IFERROR('Verkoopprognose'!C130*Aannames!B24,0) | G9: =IFERROR('Verkoopprognose'!C131*Aannames!B24,0) | H9: =IFERROR('Verkoopprognose'!C132*Aannames!B24,0) | I9: =IFERROR('Verkoopprognose'!C133*Aannames!B24,0) | J9: =IFERROR('Verkoopprognose'!C134*Aannames!B24,0) | K9: =IFERROR('Verkoopprognose'!C135*Aannames!B24,0) | L9: =IFERROR('Verkoopprognose'!C136*Aannames!B24,0) | M9: =IFERROR('Verkoopprognose'!C137*Aannames!B24,0) | N9: =IFERROR('Verkoopprognose'!C138*Aannames!B24,0) | O9: =IFERROR('Verkoopprognose'!C139*Aannames!B24,0) | P9: =IFERROR('Verkoopprognose'!C140*Aannames!B24,0) | Q9: =IFERROR('Verkoopprognose'!C141*Aannames!B24,0) | R9: =IFERROR('Verkoopprognose'!C142*Aannames!B24,0) | S9: =IFERROR('Verkoopprognose'!C143*Aannames!B24,0) | T9: =IFERROR('Verkoopprognose'!C144*Aannames!B24,0) | U9: =IFERROR('Verkoopprognose'!C145*Aannames!B24,0) | V9: =IFERROR('Verkoopprognose'!C146*Aannames!B24,0) | W9: =IFERROR('Verkoopprognose'!C147*Aannames!B24,0) | X9: =IFERROR('Verkoopprognose'!C148*Aannames!B24,0) | Y9: =IFERROR('Verkoopprognose'!C149*Aannames!B24,0) | Z9: =IFERROR('Verkoopprognose'!C150*Aannames!B24,0) | AA9: =IFERROR('Verkoopprognose'!C151*Aannames!B24,0) | AB9: =IFERROR('Verkoopprognose'!C152*Aannames!B24,0) | AC9: =IFERROR('Verkoopprognose'!C153*Aannames!B24,0) | AD9: =IFERROR('Verkoopprognose'!C154*Aannames!B24,0) | AE9: =IFERROR('Verkoopprognose'!C155*Aannames!B24,0) | AF9: =IFERROR('Verkoopprognose'!C156*Aannames!B24,0) | AG9: =IFERROR('Verkoopprognose'!C157*Aannames!B24,0) | AH9: =IFERROR('Verkoopprognose'!C158*Aannames!B24,0) | AI9: =IFERROR('Verkoopprognose'!C159*Aannames!B24,0) | AJ9: =IFERROR('Verkoopprognose'!C160*Aannames!B24,0) | AK9: =IFERROR('Verkoopprognose'!C161*Aannames!B24,0)
A10: Onderdelen en accessoires | B10: =IFERROR(Aannames!B42*(B5+B6+B7),0) | C10: =IFERROR(Aannames!B42*(C5+C6+C7),0) | D10: =IFERROR(Aannames!B42*(D5+D6+D7),0) | E10: =IFERROR(Aannames!B42*(E5+E6+E7),0) | F10: =IFERROR(Aannames!B42*(F5+F6+F7),0) | G10: =IFERROR(Aannames!B42*(G5+G6+G7),0) | H10: =IFERROR(Aannames!B42*(H5+H6+H7),0) | I10: =IFERROR(Aannames!B42*(I5+I6+I7),0) | J10: =IFERROR(Aannames!B42*(J5+J6+J7),0) | K10: =IFERROR(Aannames!B42*(K5+K6+K7),0) | L10: =IFERROR(Aannames!B42*(L5+L6+L7),0) | M10: =IFERROR(Aannames!B42*(M5+M6+M7),0) | N10: =IFERROR(Aannames!B42*(N5+N6+N7),0) | O10: =IFERROR(Aannames!B42*(O5+O6+O7),0) | P10: =IFERROR(Aannames!B42*(P5+P6+P7),0) | Q10: =IFERROR(Aannames!B42*(Q5+Q6+Q7),0) | R10: =IFERROR(Aannames!B42*(R5+R6+R7),0) | S10: =IFERROR(Aannames!B42*(S5+S6+S7),0) | T10: =IFERROR(Aannames!B42*(T5+T6+T7),0) | U10: =IFERROR(Aannames!B42*(U5+U6+U7),0) | V10: =IFERROR(Aannames!B42*(V5+V6+V7),0) | W10: =IFERROR(Aannames!B42*(W5+W6+W7),0) | X10: =IFERROR(Aannames!B42*(X5+X6+X7),0) | Y10: =IFERROR(Aannames!B42*(Y5+Y6+Y7),0) | Z10: =IFERROR(Aannames!B42*(Z5+Z6+Z7),0) | AA10: =IFERROR(Aannames!B42*(AA5+AA6+AA7),0) | AB10: =IFERROR(Aannames!B42*(AB5+AB6+AB7),0) | AC10: =IFERROR(Aannames!B42*(AC5+AC6+AC7),0) | AD10: =IFERROR(Aannames!B42*(AD5+AD6+AD7),0) | AE10: =IFERROR(Aannames!B42*(AE5+AE6+AE7),0) | AF10: =IFERROR(Aannames!B42*(AF5+AF6+AF7),0) | AG10: =IFERROR(Aannames!B42*(AG5+AG6+AG7),0) | AH10: =IFERROR(Aannames!B42*(AH5+AH6+AH7),0) | AI10: =IFERROR(Aannames!B42*(AI5+AI6+AI7),0) | AJ10: =IFERROR(Aannames!B42*(AJ5+AJ6+AJ7),0) | AK10: =IFERROR(Aannames!B42*(AK5+AK6+AK7),0)
A11: Kickback zonnepanelen | B11: =IFERROR('Verkoopprognose'!C166*Aannames!B27*Aannames!B28,0) | C11: =IFERROR('Verkoopprognose'!C167*Aannames!B27*Aannames!B28,0) | D11: =IFERROR('Verkoopprognose'!C168*Aannames!B27*Aannames!B28,0) | E11: =IFERROR('Verkoopprognose'!C169*Aannames!B27*Aannames!B28,0) | F11: =IFERROR('Verkoopprognose'!C170*Aannames!B27*Aannames!B28,0) | G11: =IFERROR('Verkoopprognose'!C171*Aannames!B27*Aannames!B28,0) | H11: =IFERROR('Verkoopprognose'!C172*Aannames!B27*Aannames!B28,0) | I11: =IFERROR('Verkoopprognose'!C173*Aannames!B27*Aannames!B28,0) | J11: =IFERROR('Verkoopprognose'!C174*Aannames!B27*Aannames!B28,0) | K11: =IFERROR('Verkoopprognose'!C175*Aannames!B27*Aannames!B28,0) | L11: =IFERROR('Verkoopprognose'!C176*Aannames!B27*Aannames!B28,0) | M11: =IFERROR('Verkoopprognose'!C177*Aannames!B27*Aannames!B28,0) | N11: =IFERROR('Verkoopprognose'!C178*Aannames!B27*Aannames!B28,0) | O11: =IFERROR('Verkoopprognose'!C179*Aannames!B27*Aannames!B28,0) | P11: =IFERROR('Verkoopprognose'!C180*Aannames!B27*Aannames!B28,0) | Q11: =IFERROR('Verkoopprognose'!C181*Aannames!B27*Aannames!B28,0) | R11: =IFERROR('Verkoopprognose'!C182*Aannames!B27*Aannames!B28,0) | S11: =IFERROR('Verkoopprognose'!C183*Aannames!B27*Aannames!B28,0) | T11: =IFERROR('Verkoopprognose'!C184*Aannames!B27*Aannames!B28,0) | U11: =IFERROR('Verkoopprognose'!C185*Aannames!B27*Aannames!B28,0) | V11: =IFERROR('Verkoopprognose'!C186*Aannames!B27*Aannames!B28,0) | W11: =IFERROR('Verkoopprognose'!C187*Aannames!B27*Aannames!B28,0) | X11: =IFERROR('Verkoopprognose'!C188*Aannames!B27*Aannames!B28,0) | Y11: =IFERROR('Verkoopprognose'!C189*Aannames!B27*Aannames!B28,0) | Z11: =IFERROR('Verkoopprognose'!C190*Aannames!B27*Aannames!B28,0) | AA11: =IFERROR('Verkoopprognose'!C191*Aannames!B27*Aannames!B28,0) | AB11: =IFERROR('Verkoopprognose'!C192*Aannames!B27*Aannames!B28,0) | AC11: =IFERROR('Verkoopprognose'!C193*Aannames!B27*Aannames!B28,0) | AD11: =IFERROR('Verkoopprognose'!C194*Aannames!B27*Aannames!B28,0) | AE11: =IFERROR('Verkoopprognose'!C195*Aannames!B27*Aannames!B28,0) | AF11: =IFERROR('Verkoopprognose'!C196*Aannames!B27*Aannames!B28,0) | AG11: =IFERROR('Verkoopprognose'!C197*Aannames!B27*Aannames!B28,0) | AH11: =IFERROR('Verkoopprognose'!C198*Aannames!B27*Aannames!B28,0) | AI11: =IFERROR('Verkoopprognose'!C199*Aannames!B27*Aannames!B28,0) | AJ11: =IFERROR('Verkoopprognose'!C200*Aannames!B27*Aannames!B28,0) | AK11: =IFERROR('Verkoopprognose'!C201*Aannames!B27*Aannames!B28,0)
A12: Extra garantie | B12: =IFERROR('Verkoopprognose'!C206*Aannames!B31*Aannames!B32,0) | C12: =IFERROR('Verkoopprognose'!C207*Aannames!B31*Aannames!B32,0) | D12: =IFERROR('Verkoopprognose'!C208*Aannames!B31*Aannames!B32,0) | E12: =IFERROR('Verkoopprognose'!C209*Aannames!B31*Aannames!B32,0) | F12: =IFERROR('Verkoopprognose'!C210*Aannames!B31*Aannames!B32,0) | G12: =IFERROR('Verkoopprognose'!C211*Aannames!B31*Aannames!B32,0) | H12: =IFERROR('Verkoopprognose'!C212*Aannames!B31*Aannames!B32,0) | I12: =IFERROR('Verkoopprognose'!C213*Aannames!B31*Aannames!B32,0) | J12: =IFERROR('Verkoopprognose'!C214*Aannames!B31*Aannames!B32,0) | K12: =IFERROR('Verkoopprognose'!C215*Aannames!B31*Aannames!B32,0) | L12: =IFERROR('Verkoopprognose'!C216*Aannames!B31*Aannames!B32,0) | M12: =IFERROR('Verkoopprognose'!C217*Aannames!B31*Aannames!B32,0) | N12: =IFERROR('Verkoopprognose'!C218*Aannames!B31*Aannames!B32,0) | O12: =IFERROR('Verkoopprognose'!C219*Aannames!B31*Aannames!B32,0) | P12: =IFERROR('Verkoopprognose'!C220*Aannames!B31*Aannames!B32,0) | Q12: =IFERROR('Verkoopprognose'!C221*Aannames!B31*Aannames!B32,0) | R12: =IFERROR('Verkoopprognose'!C222*Aannames!B31*Aannames!B32,0) | S12: =IFERROR('Verkoopprognose'!C223*Aannames!B31*Aannames!B32,0) | T12: =IFERROR('Verkoopprognose'!C224*Aannames!B31*Aannames!B32,0) | U12: =IFERROR('Verkoopprognose'!C225*Aannames!B31*Aannames!B32,0) | V12: =IFERROR('Verkoopprognose'!C226*Aannames!B31*Aannames!B32,0) | W12: =IFERROR('Verkoopprognose'!C227*Aannames!B31*Aannames!B32,0) | X12: =IFERROR('Verkoopprognose'!C228*Aannames!B31*Aannames!B32,0) | Y12: =IFERROR('Verkoopprognose'!C229*Aannames!B31*Aannames!B32,0) | Z12: =IFERROR('Verkoopprognose'!C230*Aannames!B31*Aannames!B32,0) | AA12: =IFERROR('Verkoopprognose'!C231*Aannames!B31*Aannames!B32,0) | AB12: =IFERROR('Verkoopprognose'!C232*Aannames!B31*Aannames!B32,0) | AC12: =IFERROR('Verkoopprognose'!C233*Aannames!B31*Aannames!B32,0) | AD12: =IFERROR('Verkoopprognose'!C234*Aannames!B31*Aannames!B32,0) | AE12: =IFERROR('Verkoopprognose'!C235*Aannames!B31*Aannames!B32,0) | AF12: =IFERROR('Verkoopprognose'!C236*Aannames!B31*Aannames!B32,0) | AG12: =IFERROR('Verkoopprognose'!C237*Aannames!B31*Aannames!B32,0) | AH12: =IFERROR('Verkoopprognose'!C238*Aannames!B31*Aannames!B32,0) | AI12: =IFERROR('Verkoopprognose'!C239*Aannames!B31*Aannames!B32,0) | AJ12: =IFERROR('Verkoopprognose'!C240*Aannames!B31*Aannames!B32,0) | AK12: =IFERROR('Verkoopprognose'!C241*Aannames!B31*Aannames!B32,0)
A13: TOTALE OMZET | B13: =IFERROR(SUM(B5:B12),0) | C13: =IFERROR(SUM(C5:C12),0) | D13: =IFERROR(SUM(D5:D12),0) | E13: =IFERROR(SUM(E5:E12),0) | F13: =IFERROR(SUM(F5:F12),0) | G13: =IFERROR(SUM(G5:G12),0) | H13: =IFERROR(SUM(H5:H12),0) | I13: =IFERROR(SUM(I5:I12),0) | ... AK13: =IFERROR(SUM(AK5:AK12),0)
A15: KOSTEN
A16: Inkoop batterijsystemen | B16: =IFERROR('Verkoopprognose'!C6*Kosten!C6,0) | C16: =IFERROR('Verkoopprognose'!C7*Kosten!C6,0) | D16: =IFERROR('Verkoopprognose'!C8*Kosten!C6,0) | E16: =IFERROR('Verkoopprognose'!C9*Kosten!C6,0) | F16: =IFERROR('Verkoopprognose'!C10*Kosten!C6,0) | G16: =IFERROR('Verkoopprognose'!C11*Kosten!C6,0) | H16: =IFERROR('Verkoopprognose'!C12*Kosten!C6,0) | I16: =IFERROR('Verkoopprognose'!C13*Kosten!C6,0) | J16: =IFERROR('Verkoopprognose'!C14*Kosten!C6,0) | K16: =IFERROR('Verkoopprognose'!C15*Kosten!C6,0) | L16: =IFERROR('Verkoopprognose'!C16*Kosten!C6,0) | M16: =IFERROR('Verkoopprognose'!C17*Kosten!C6,0) | N16: =IFERROR('Verkoopprognose'!C18*Kosten!C6,0) | O16: =IFERROR('Verkoopprognose'!C19*Kosten!C6,0) | P16: =IFERROR('Verkoopprognose'!C20*Kosten!C6,0) | Q16: =IFERROR('Verkoopprognose'!C21*Kosten!C6,0) | R16: =IFERROR('Verkoopprognose'!C22*Kosten!C6,0) | S16: =IFERROR('Verkoopprognose'!C23*Kosten!C6,0) | T16: =IFERROR('Verkoopprognose'!C24*Kosten!C6,0) | U16: =IFERROR('Verkoopprognose'!C25*Kosten!C6,0) | V16: =IFERROR('Verkoopprognose'!C26*Kosten!C6,0) | W16: =IFERROR('Verkoopprognose'!C27*Kosten!C6,0) | X16: =IFERROR('Verkoopprognose'!C28*Kosten!C6,0) | Y16: =IFERROR('Verkoopprognose'!C29*Kosten!C6,0) | Z16: =IFERROR('Verkoopprognose'!C30*Kosten!C6,0) | AA16: =IFERROR('Verkoopprognose'!C31*Kosten!C6,0) | AB16: =IFERROR('Verkoopprognose'!C32*Kosten!C6,0) | AC16: =IFERROR('Verkoopprognose'!C33*Kosten!C6,0) | AD16: =IFERROR('Verkoopprognose'!C34*Kosten!C6,0) | AE16: =IFERROR('Verkoopprognose'!C35*Kosten!C6,0) | AF16: =IFERROR('Verkoopprognose'!C36*Kosten!C6,0) | AG16: =IFERROR('Verkoopprognose'!C37*Kosten!C6,0) | AH16: =IFERROR('Verkoopprognose'!C38*Kosten!C6,0) | AI16: =IFERROR('Verkoopprognose'!C39*Kosten!C6,0) | AJ16: =IFERROR('Verkoopprognose'!C40*Kosten!C6,0) | AK16: =IFERROR('Verkoopprognose'!C41*Kosten!C6,0)
A17: Inkoop AC laadpalen | B17: =IFERROR('Verkoopprognose'!C46*Kosten!C7,0) | C17: =IFERROR('Verkoopprognose'!C47*Kosten!C7,0) | D17: =IFERROR('Verkoopprognose'!C48*Kosten!C7,0) | E17: =IFERROR('Verkoopprognose'!C49*Kosten!C7,0) | F17: =IFERROR('Verkoopprognose'!C50*Kosten!C7,0) | G17: =IFERROR('Verkoopprognose'!C51*Kosten!C7,0) | H17: =IFERROR('Verkoopprognose'!C52*Kosten!C7,0) | I17: =IFERROR('Verkoopprognose'!C53*Kosten!C7,0) | J17: =IFERROR('Verkoopprognose'!C54*Kosten!C7,0) | K17: =IFERROR('Verkoopprognose'!C55*Kosten!C7,0) | L17: =IFERROR('Verkoopprognose'!C56*Kosten!C7,0) | M17: =IFERROR('Verkoopprognose'!C57*Kosten!C7,0) | N17: =IFERROR('Verkoopprognose'!C58*Kosten!C7,0) | O17: =IFERROR('Verkoopprognose'!C59*Kosten!C7,0) | P17: =IFERROR('Verkoopprognose'!C60*Kosten!C7,0) | Q17: =IFERROR('Verkoopprognose'!C61*Kosten!C7,0) | R17: =IFERROR('Verkoopprognose'!C62*Kosten!C7,0) | S17: =IFERROR('Verkoopprognose'!C63*Kosten!C7,0) | T17: =IFERROR('Verkoopprognose'!C64*Kosten!C7,0) | U17: =IFERROR('Verkoopprognose'!C65*Kosten!C7,0) | V17: =IFERROR('Verkoopprognose'!C66*Kosten!C7,0) | W17: =IFERROR('Verkoopprognose'!C67*Kosten!C7,0) | X17: =IFERROR('Verkoopprognose'!C68*Kosten!C7,0) | Y17: =IFERROR('Verkoopprognose'!C69*Kosten!C7,0) | Z17: =IFERROR('Verkoopprognose'!C70*Kosten!C7,0) | AA17: =IFERROR('Verkoopprognose'!C71*Kosten!C7,0) | AB17: =IFERROR('Verkoopprognose'!C72*Kosten!C7,0) | AC17: =IFERROR('Verkoopprognose'!C73*Kosten!C7,0) | AD17: =IFERROR('Verkoopprognose'!C74*Kosten!C7,0) | AE17: =IFERROR('Verkoopprognose'!C75*Kosten!C7,0) | AF17: =IFERROR('Verkoopprognose'!C76*Kosten!C7,0) | AG17: =IFERROR('Verkoopprognose'!C77*Kosten!C7,0) | AH17: =IFERROR('Verkoopprognose'!C78*Kosten!C7,0) | AI17: =IFERROR('Verkoopprognose'!C79*Kosten!C7,0) | AJ17: =IFERROR('Verkoopprognose'!C80*Kosten!C7,0) | AK17: =IFERROR('Verkoopprognose'!C81*Kosten!C7,0)
A18: Inkoop DC snelladers | B18: =IFERROR('Verkoopprognose'!C86*Kosten!C8,0) | C18: =IFERROR('Verkoopprognose'!C87*Kosten!C8,0) | D18: =IFERROR('Verkoopprognose'!C88*Kosten!C8,0) | E18: =IFERROR('Verkoopprognose'!C89*Kosten!C8,0) | F18: =IFERROR('Verkoopprognose'!C90*Kosten!C8,0) | G18: =IFERROR('Verkoopprognose'!C91*Kosten!C8,0) | H18: =IFERROR('Verkoopprognose'!C92*Kosten!C8,0) | I18: =IFERROR('Verkoopprognose'!C93*Kosten!C8,0) | J18: =IFERROR('Verkoopprognose'!C94*Kosten!C8,0) | K18: =IFERROR('Verkoopprognose'!C95*Kosten!C8,0) | L18: =IFERROR('Verkoopprognose'!C96*Kosten!C8,0) | M18: =IFERROR('Verkoopprognose'!C97*Kosten!C8,0) | N18: =IFERROR('Verkoopprognose'!C98*Kosten!C8,0) | O18: =IFERROR('Verkoopprognose'!C99*Kosten!C8,0) | P18: =IFERROR('Verkoopprognose'!C100*Kosten!C8,0) | Q18: =IFERROR('Verkoopprognose'!C101*Kosten!C8,0) | R18: =IFERROR('Verkoopprognose'!C102*Kosten!C8,0) | S18: =IFERROR('Verkoopprognose'!C103*Kosten!C8,0) | T18: =IFERROR('Verkoopprognose'!C104*Kosten!C8,0) | U18: =IFERROR('Verkoopprognose'!C105*Kosten!C8,0) | V18: =IFERROR('Verkoopprognose'!C106*Kosten!C8,0) | W18: =IFERROR('Verkoopprognose'!C107*Kosten!C8,0) | X18: =IFERROR('Verkoopprognose'!C108*Kosten!C8,0) | Y18: =IFERROR('Verkoopprognose'!C109*Kosten!C8,0) | Z18: =IFERROR('Verkoopprognose'!C110*Kosten!C8,0) | AA18: =IFERROR('Verkoopprognose'!C111*Kosten!C8,0) | AB18: =IFERROR('Verkoopprognose'!C112*Kosten!C8,0) | AC18: =IFERROR('Verkoopprognose'!C113*Kosten!C8,0) | AD18: =IFERROR('Verkoopprognose'!C114*Kosten!C8,0) | AE18: =IFERROR('Verkoopprognose'!C115*Kosten!C8,0) | AF18: =IFERROR('Verkoopprognose'!C116*Kosten!C8,0) | AG18: =IFERROR('Verkoopprognose'!C117*Kosten!C8,0) | AH18: =IFERROR('Verkoopprognose'!C118*Kosten!C8,0) | AI18: =IFERROR('Verkoopprognose'!C119*Kosten!C8,0) | AJ18: =IFERROR('Verkoopprognose'!C120*Kosten!C8,0) | AK18: =IFERROR('Verkoopprognose'!C121*Kosten!C8,0)
A19: Installatie en logistiek | B19: =IFERROR('Verkoopprognose'!C6*Kosten!C12+'Verkoopprognose'!C46*Kosten!C13+'Verkoopprognose'!C86*Kosten!C14+Kosten!C15,0) | C19: =IFERROR('Verkoopprognose'!C7*Kosten!C12+'Verkoopprognose'!C47*Kosten!C13+'Verkoopprognose'!C87*Kosten!C14+Kosten!C15,0) | D19: =IFERROR('Verkoopprognose'!C8*Kosten!C12+'Verkoopprognose'!C48*Kosten!C13+'Verkoopprognose'!C88*Kosten!C14+Kosten!C15,0) | E19: =IFERROR('Verkoopprognose'!C9*Kosten!C12+'Verkoopprognose'!C49*Kosten!C13+'Verkoopprognose'!C89*Kosten!C14+Kosten!C15,0) | F19: =IFERROR('Verkoopprognose'!C10*Kosten!C12+'Verkoopprognose'!C50*Kosten!C13+'Verkoopprognose'!C90*Kosten!C14+Kosten!C15,0) | G19: =IFERROR('Verkoopprognose'!C11*Kosten!C12+'Verkoopprognose'!C51*Kosten!C13+'Verkoopprognose'!C91*Kosten!C14+Kosten!C15,0) | H19: =IFERROR('Verkoopprognose'!C12*Kosten!C12+'Verkoopprognose'!C52*Kosten!C13+'Verkoopprognose'!C92*Kosten!C14+Kosten!C15,0) | I19: =IFERROR('Verkoopprognose'!C13*Kosten!C12+'Verkoopprognose'!C53*Kosten!C13+'Verkoopprognose'!C93*Kosten!C14+Kosten!C15,0) | J19: =IFERROR('Verkoopprognose'!C14*Kosten!C12+'Verkoopprognose'!C54*Kosten!C13+'Verkoopprognose'!C94*Kosten!C14+Kosten!C15,0) | K19: =IFERROR('Verkoopprognose'!C15*Kosten!C12+'Verkoopprognose'!C55*Kosten!C13+'Verkoopprognose'!C95*Kosten!C14+Kosten!C15,0) | L19: =IFERROR('Verkoopprognose'!C16*Kosten!C12+'Verkoopprognose'!C56*Kosten!C13+'Verkoopprognose'!C96*Kosten!C14+Kosten!C15,0) | M19: =IFERROR('Verkoopprognose'!C17*Kosten!C12+'Verkoopprognose'!C57*Kosten!C13+'Verkoopprognose'!C97*Kosten!C14+Kosten!C15,0) | N19: =IFERROR('Verkoopprognose'!C18*Kosten!C12+'Verkoopprognose'!C58*Kosten!C13+'Verkoopprognose'!C98*Kosten!C14+Kosten!C15,0) | O19: =IFERROR('Verkoopprognose'!C19*Kosten!C12+'Verkoopprognose'!C59*Kosten!C13+'Verkoopprognose'!C99*Kosten!C14+Kosten!C15,0) | P19: =IFERROR('Verkoopprognose'!C20*Kosten!C12+'Verkoopprognose'!C60*Kosten!C13+'Verkoopprognose'!C100*Kosten!C14+Kosten!C15,0) | Q19: =IFERROR('Verkoopprognose'!C21*Kosten!C12+'Verkoopprognose'!C61*Kosten!C13+'Verkoopprognose'!C101*Kosten!C14+Kosten!C15,0) | R19: =IFERROR('Verkoopprognose'!C22*Kosten!C12+'Verkoopprognose'!C62*Kosten!C13+'Verkoopprognose'!C102*Kosten!C14+Kosten!C15,0) | S19: =IFERROR('Verkoopprognose'!C23*Kosten!C12+'Verkoopprognose'!C63*Kosten!C13+'Verkoopprognose'!C103*Kosten!C14+Kosten!C15,0) | T19: =IFERROR('Verkoopprognose'!C24*Kosten!C12+'Verkoopprognose'!C64*Kosten!C13+'Verkoopprognose'!C104*Kosten!C14+Kosten!C15,0) | U19: =IFERROR('Verkoopprognose'!C25*Kosten!C12+'Verkoopprognose'!C65*Kosten!C13+'Verkoopprognose'!C105*Kosten!C14+Kosten!C15,0) | V19: =IFERROR('Verkoopprognose'!C26*Kosten!C12+'Verkoopprognose'!C66*Kosten!C13+'Verkoopprognose'!C106*Kosten!C14+Kosten!C15,0) | W19: =IFERROR('Verkoopprognose'!C27*Kosten!C12+'Verkoopprognose'!C67*Kosten!C13+'Verkoopprognose'!C107*Kosten!C14+Kosten!C15,0) | X19: =IFERROR('Verkoopprognose'!C28*Kosten!C12+'Verkoopprognose'!C68*Kosten!C13+'Verkoopprognose'!C108*Kosten!C14+Kosten!C15,0) | Y19: =IFERROR('Verkoopprognose'!C29*Kosten!C12+'Verkoopprognose'!C69*Kosten!C13+'Verkoopprognose'!C109*Kosten!C14+Kosten!C15,0) | Z19: =IFERROR('Verkoopprognose'!C30*Kosten!C12+'Verkoopprognose'!C70*Kosten!C13+'Verkoopprognose'!C110*Kosten!C14+Kosten!C15,0) | AA19: =IFERROR('Verkoopprognose'!C31*Kosten!C12+'Verkoopprognose'!C71*Kosten!C13+'Verkoopprognose'!C111*Kosten!C14+Kosten!C15,0) | AB19: =IFERROR('Verkoopprognose'!C32*Kosten!C12+'Verkoopprognose'!C72*Kosten!C13+'Verkoopprognose'!C112*Kosten!C14+Kosten!C15,0) | AC19: =IFERROR('Verkoopprognose'!C33*Kosten!C12+'Verkoopprognose'!C73*Kosten!C13+'Verkoopprognose'!C113*Kosten!C14+Kosten!C15,0) | AD19: =IFERROR('Verkoopprognose'!C34*Kosten!C12+'Verkoopprognose'!C74*Kosten!C13+'Verkoopprognose'!C114*Kosten!C14+Kosten!C15,0) | AE19: =IFERROR('Verkoopprognose'!C35*Kosten!C12+'Verkoopprognose'!C75*Kosten!C13+'Verkoopprognose'!C115*Kosten!C14+Kosten!C15,0) | AF19: =IFERROR('Verkoopprognose'!C36*Kosten!C12+'Verkoopprognose'!C76*Kosten!C13+'Verkoopprognose'!C116*Kosten!C14+Kosten!C15,0) | AG19: =IFERROR('Verkoopprognose'!C37*Kosten!C12+'Verkoopprognose'!C77*Kosten!C13+'Verkoopprognose'!C117*Kosten!C14+Kosten!C15,0) | AH19: =IFERROR('Verkoopprognose'!C38*Kosten!C12+'Verkoopprognose'!C78*Kosten!C13+'Verkoopprognose'!C118*Kosten!C14+Kosten!C15,0) | AI19: =IFERROR('Verkoopprognose'!C39*Kosten!C12+'Verkoopprognose'!C79*Kosten!C13+'Verkoopprognose'!C119*Kosten!C14+Kosten!C15,0) | AJ19: =IFERROR('Verkoopprognose'!C40*Kosten!C12+'Verkoopprognose'!C80*Kosten!C13+'Verkoopprognose'!C120*Kosten!C14+Kosten!C15,0) | AK19: =IFERROR('Verkoopprognose'!C41*Kosten!C12+'Verkoopprognose'!C81*Kosten!C13+'Verkoopprognose'!C121*Kosten!C14+Kosten!C15,0)
A20: Personeel | B20: =IFERROR(Kosten!C19*(1+Kosten!C22)+Kosten!C23,0) | C20: =IFERROR(Kosten!C19*(1+Kosten!C22)+Kosten!C23,0) | D20: =IFERROR(Kosten!C19*(1+Kosten!C22)+Kosten!C23,0) | E20: =IFERROR(Kosten!C19*(1+Kosten!C22)+Kosten!C23,0) | F20: =IFERROR(Kosten!C19*(1+Kosten!C22)+Kosten!C23,0) | G20: =IFERROR(Kosten!C19*(1+Kosten!C22)+Kosten!C23,0) | H20: =IFERROR(Kosten!C19*(1+Kosten!C22)+Kosten!C23,0) | I20: =IFERROR(Kosten!C19*(1+Kosten!C22)+Kosten!C23,0) | J20: =IFERROR(Kosten!C19*(1+Kosten!C22)+Kosten!C23,0) | K20: =IFERROR(Kosten!C19*(1+Kosten!C22)+Kosten!C23,0) | L20: =IFERROR(Kosten!C19*(1+Kosten!C22)+Kosten!C23,0) | M20: =IFERROR(Kosten!C19*(1+Kosten!C22)+Kosten!C23,0) | N20: =IFERROR(Kosten!C20*(1+Kosten!C22)+Kosten!C23,0) | O20: =IFERROR(Kosten!C20*(1+Kosten!C22)+Kosten!C23,0) | P20: =IFERROR(Kosten!C20*(1+Kosten!C22)+Kosten!C23,0) | Q20: =IFERROR(Kosten!C20*(1+Kosten!C22)+Kosten!C23,0) | R20: =IFERROR(Kosten!C20*(1+Kosten!C22)+Kosten!C23,0) | S20: =IFERROR(Kosten!C20*(1+Kosten!C22)+Kosten!C23,0) | T20: =IFERROR(Kosten!C20*(1+Kosten!C22)+Kosten!C23,0) | U20: =IFERROR(Kosten!C20*(1+Kosten!C22)+Kosten!C23,0) | V20: =IFERROR(Kosten!C20*(1+Kosten!C22)+Kosten!C23,0) | W20: =IFERROR(Kosten!C20*(1+Kosten!C22)+Kosten!C23,0) | X20: =IFERROR(Kosten!C20*(1+Kosten!C22)+Kosten!C23,0) | Y20: =IFERROR(Kosten!C20*(1+Kosten!C22)+Kosten!C23,0) | Z20: =IFERROR(Kosten!C21*(1+Kosten!C22)+Kosten!C23,0) | AA20: =IFERROR(Kosten!C21*(1+Kosten!C22)+Kosten!C23,0) | AB20: =IFERROR(Kosten!C21*(1+Kosten!C22)+Kosten!C23,0) | AC20: =IFERROR(Kosten!C21*(1+Kosten!C22)+Kosten!C23,0) | AD20: =IFERROR(Kosten!C21*(1+Kosten!C22)+Kosten!C23,0) | AE20: =IFERROR(Kosten!C21*(1+Kosten!C22)+Kosten!C23,0) | AF20: =IFERROR(Kosten!C21*(1+Kosten!C22)+Kosten!C23,0) | AG20: =IFERROR(Kosten!C21*(1+Kosten!C22)+Kosten!C23,0) | AH20: =IFERROR(Kosten!C21*(1+Kosten!C22)+Kosten!C23,0) | AI20: =IFERROR(Kosten!C21*(1+Kosten!C22)+Kosten!C23,0) | AJ20: =IFERROR(Kosten!C21*(1+Kosten!C22)+Kosten!C23,0) | AK20: =IFERROR(Kosten!C21*(1+Kosten!C22)+Kosten!C23,0)
A21: Marketing en sales | B21: =IFERROR(Kosten!C27+Kosten!C28+Kosten!C29+Kosten!C31+Kosten!C30*B13,0) | C21: =IFERROR(Kosten!C27+Kosten!C28+Kosten!C29+Kosten!C31+Kosten!C30*C13,0) | D21: =IFERROR(Kosten!C27+Kosten!C28+Kosten!C29+Kosten!C31+Kosten!C30*D13,0) | E21: =IFERROR(Kosten!C27+Kosten!C28+Kosten!C29+Kosten!C31+Kosten!C30*E13,0) | F21: =IFERROR(Kosten!C27+Kosten!C28+Kosten!C29+Kosten!C31+Kosten!C30*F13,0) | G21: =IFERROR(Kosten!C27+Kosten!C28+Kosten!C29+Kosten!C31+Kosten!C30*G13,0) | H21: =IFERROR(Kosten!C27+Kosten!C28+Kosten!C29+Kosten!C31+Kosten!C30*H13,0) | I21: =IFERROR(Kosten!C27+Kosten!C28+Kosten!C29+Kosten!C31+Kosten!C30*I13,0) | J21: =IFERROR(Kosten!C27+Kosten!C28+Kosten!C29+Kosten!C31+Kosten!C30*J13,0) | K21: =IFERROR(Kosten!C27+Kosten!C28+Kosten!C29+Kosten!C31+Kosten!C30*K13,0) | L21: =IFERROR(Kosten!C27+Kosten!C28+Kosten!C29+Kosten!C31+Kosten!C30*L13,0) | M21: =IFERROR(Kosten!C27+Kosten!C28+Kosten!C29+Kosten!C31+Kosten!C30*M13,0) | N21: =IFERROR(Kosten!C27+Kosten!C28+Kosten!C29+Kosten!C31+Kosten!C30*N13,0) | O21: =IFERROR(Kosten!C27+Kosten!C28+Kosten!C29+Kosten!C31+Kosten!C30*O13,0) | P21: =IFERROR(Kosten!C27+Kosten!C28+Kosten!C29+Kosten!C31+Kosten!C30*P13,0) | Q21: =IFERROR(Kosten!C27+Kosten!C28+Kosten!C29+Kosten!C31+Kosten!C30*Q13,0) | R21: =IFERROR(Kosten!C27+Kosten!C28+Kosten!C29+Kosten!C31+Kosten!C30*R13,0) | S21: =IFERROR(Kosten!C27+Kosten!C28+Kosten!C29+Kosten!C31+Kosten!C30*S13,0) | T21: =IFERROR(Kosten!C27+Kosten!C28+Kosten!C29+Kosten!C31+Kosten!C30*T13,0) | U21: =IFERROR(Kosten!C27+Kosten!C28+Kosten!C29+Kosten!C31+Kosten!C30*U13,0) | V21: =IFERROR(Kosten!C27+Kosten!C28+Kosten!C29+Kosten!C31+Kosten!C30*V13,0) | W21: =IFERROR(Kosten!C27+Kosten!C28+Kosten!C29+Kosten!C31+Kosten!C30*W13,0) | X21: =IFERROR(Kosten!C27+Kosten!C28+Kosten!C29+Kosten!C31+Kosten!C30*X13,0) | Y21: =IFERROR(Kosten!C27+Kosten!C28+Kosten!C29+Kosten!C31+Kosten!C30*Y13,0) | Z21: =IFERROR(Kosten!C27+Kosten!C28+Kosten!C29+Kosten!C31+Kosten!C30*Z13,0) | AA21: =IFERROR(Kosten!C27+Kosten!C28+Kosten!C29+Kosten!C31+Kosten!C30*AA13,0) | AB21: =IFERROR(Kosten!C27+Kosten!C28+Kosten!C29+Kosten!C31+Kosten!C30*AB13,0) | AC21: =IFERROR(Kosten!C27+Kosten!C28+Kosten!C29+Kosten!C31+Kosten!C30*AC13,0) | AD21: =IFERROR(Kosten!C27+Kosten!C28+Kosten!C29+Kosten!C31+Kosten!C30*AD13,0) | AE21: =IFERROR(Kosten!C27+Kosten!C28+Kosten!C29+Kosten!C31+Kosten!C30*AE13,0) | AF21: =IFERROR(Kosten!C27+Kosten!C28+Kosten!C29+Kosten!C31+Kosten!C30*AF13,0) | AG21: =IFERROR(Kosten!C27+Kosten!C28+Kosten!C29+Kosten!C31+Kosten!C30*AG13,0) | AH21: =IFERROR(Kosten!C27+Kosten!C28+Kosten!C29+Kosten!C31+Kosten!C30*AH13,0) | AI21: =IFERROR(Kosten!C27+Kosten!C28+Kosten!C29+Kosten!C31+Kosten!C30*AI13,0) | AJ21: =IFERROR(Kosten!C27+Kosten!C28+Kosten!C29+Kosten!C31+Kosten!C30*AJ13,0) | AK21: =IFERROR(Kosten!C27+Kosten!C28+Kosten!C29+Kosten!C31+Kosten!C30*AK13,0)
A22: Kantoor en operations | B22: =IFERROR(Kosten!C35+Kosten!C36+Kosten!C37+Kosten!C38,0) | C22: =IFERROR(Kosten!C35+Kosten!C36+Kosten!C37+Kosten!C38,0) | D22: =IFERROR(Kosten!C35+Kosten!C36+Kosten!C37+Kosten!C38,0) | E22: =IFERROR(Kosten!C35+Kosten!C36+Kosten!C37+Kosten!C38,0) | F22: =IFERROR(Kosten!C35+Kosten!C36+Kosten!C37+Kosten!C38,0) | G22: =IFERROR(Kosten!C35+Kosten!C36+Kosten!C37+Kosten!C38,0) | H22: =IFERROR(Kosten!C35+Kosten!C36+Kosten!C37+Kosten!C38,0) | I22: =IFERROR(Kosten!C35+Kosten!C36+Kosten!C37+Kosten!C38,0) | J22: =IFERROR(Kosten!C35+Kosten!C36+Kosten!C37+Kosten!C38,0) | K22: =IFERROR(Kosten!C35+Kosten!C36+Kosten!C37+Kosten!C38,0) | L22: =IFERROR(Kosten!C35+Kosten!C36+Kosten!C37+Kosten!C38,0) | M22: =IFERROR(Kosten!C35+Kosten!C36+Kosten!C37+Kosten!C38,0) | N22: =IFERROR(Kosten!C35+Kosten!C36+Kosten!C37+Kosten!C38,0) | O22: =IFERROR(Kosten!C35+Kosten!C36+Kosten!C37+Kosten!C38,0) | P22: =IFERROR(Kosten!C35+Kosten!C36+Kosten!C37+Kosten!C38,0) | Q22: =IFERROR(Kosten!C35+Kosten!C36+Kosten!C37+Kosten!C38,0) | R22: =IFERROR(Kosten!C35+Kosten!C36+Kosten!C37+Kosten!C38,0) | S22: =IFERROR(Kosten!C35+Kosten!C36+Kosten!C37+Kosten!C38,0) | T22: =IFERROR(Kosten!C35+Kosten!C36+Kosten!C37+Kosten!C38,0) | U22: =IFERROR(Kosten!C35+Kosten!C36+Kosten!C37+Kosten!C38,0) | V22: =IFERROR(Kosten!C35+Kosten!C36+Kosten!C37+Kosten!C38,0) | W22: =IFERROR(Kosten!C35+Kosten!C36+Kosten!C37+Kosten!C38,0) | X22: =IFERROR(Kosten!C35+Kosten!C36+Kosten!C37+Kosten!C38,0) | Y22: =IFERROR(Kosten!C35+Kosten!C36+Kosten!C37+Kosten!C38,0) | Z22: =IFERROR(Kosten!C35+Kosten!C36+Kosten!C37+Kosten!C38,0) | AA22: =IFERROR(Kosten!C35+Kosten!C36+Kosten!C37+Kosten!C38,0) | AB22: =IFERROR(Kosten!C35+Kosten!C36+Kosten!C37+Kosten!C38,0) | AC22: =IFERROR(Kosten!C35+Kosten!C36+Kosten!C37+Kosten!C38,0) | AD22: =IFERROR(Kosten!C35+Kosten!C36+Kosten!C37+Kosten!C38,0) | AE22: =IFERROR(Kosten!C35+Kosten!C36+Kosten!C37+Kosten!C38,0) | AF22: =IFERROR(Kosten!C35+Kosten!C36+Kosten!C37+Kosten!C38,0) | AG22: =IFERROR(Kosten!C35+Kosten!C36+Kosten!C37+Kosten!C38,0) | AH22: =IFERROR(Kosten!C35+Kosten!C36+Kosten!C37+Kosten!C38,0) | AI22: =IFERROR(Kosten!C35+Kosten!C36+Kosten!C37+Kosten!C38,0) | AJ22: =IFERROR(Kosten!C35+Kosten!C36+Kosten!C37+Kosten!C38,0) | AK22: =IFERROR(Kosten!C35+Kosten!C36+Kosten!C37+Kosten!C38,0)
A23: Software, tools en IT | B23: =IFERROR(Kosten!C42+Kosten!C43+Kosten!C44+Kosten!C45,0) | C23: =IFERROR(Kosten!C42+Kosten!C43+Kosten!C44+Kosten!C45,0) | D23: =IFERROR(Kosten!C42+Kosten!C43+Kosten!C44+Kosten!C45,0) | E23: =IFERROR(Kosten!C42+Kosten!C43+Kosten!C44+Kosten!C45,0) | F23: =IFERROR(Kosten!C42+Kosten!C43+Kosten!C44+Kosten!C45,0) | G23: =IFERROR(Kosten!C42+Kosten!C43+Kosten!C44+Kosten!C45,0) | H23: =IFERROR(Kosten!C42+Kosten!C43+Kosten!C44+Kosten!C45,0) | I23: =IFERROR(Kosten!C42+Kosten!C43+Kosten!C44+Kosten!C45,0) | J23: =IFERROR(Kosten!C42+Kosten!C43+Kosten!C44+Kosten!C45,0) | K23: =IFERROR(Kosten!C42+Kosten!C43+Kosten!C44+Kosten!C45,0) | L23: =IFERROR(Kosten!C42+Kosten!C43+Kosten!C44+Kosten!C45,0) | M23: =IFERROR(Kosten!C42+Kosten!C43+Kosten!C44+Kosten!C45,0) | N23: =IFERROR(Kosten!C42+Kosten!C43+Kosten!C44+Kosten!C45,0) | O23: =IFERROR(Kosten!C42+Kosten!C43+Kosten!C44+Kosten!C45,0) | P23: =IFERROR(Kosten!C42+Kosten!C43+Kosten!C44+Kosten!C45,0) | Q23: =IFERROR(Kosten!C42+Kosten!C43+Kosten!C44+Kosten!C45,0) | R23: =IFERROR(Kosten!C42+Kosten!C43+Kosten!C44+Kosten!C45,0) | S23: =IFERROR(Kosten!C42+Kosten!C43+Kosten!C44+Kosten!C45,0) | T23: =IFERROR(Kosten!C42+Kosten!C43+Kosten!C44+Kosten!C45,0) | U23: =IFERROR(Kosten!C42+Kosten!C43+Kosten!C44+Kosten!C45,0) | V23: =IFERROR(Kosten!C42+Kosten!C43+Kosten!C44+Kosten!C45,0) | W23: =IFERROR(Kosten!C42+Kosten!C43+Kosten!C44+Kosten!C45,0) | X23: =IFERROR(Kosten!C42+Kosten!C43+Kosten!C44+Kosten!C45,0) | Y23: =IFERROR(Kosten!C42+Kosten!C43+Kosten!C44+Kosten!C45,0) | Z23: =IFERROR(Kosten!C42+Kosten!C43+Kosten!C44+Kosten!C45,0) | AA23: =IFERROR(Kosten!C42+Kosten!C43+Kosten!C44+Kosten!C45,0) | AB23: =IFERROR(Kosten!C42+Kosten!C43+Kosten!C44+Kosten!C45,0) | AC23: =IFERROR(Kosten!C42+Kosten!C43+Kosten!C44+Kosten!C45,0) | AD23: =IFERROR(Kosten!C42+Kosten!C43+Kosten!C44+Kosten!C45,0) | AE23: =IFERROR(Kosten!C42+Kosten!C43+Kosten!C44+Kosten!C45,0) | AF23: =IFERROR(Kosten!C42+Kosten!C43+Kosten!C44+Kosten!C45,0) | AG23: =IFERROR(Kosten!C42+Kosten!C43+Kosten!C44+Kosten!C45,0) | AH23: =IFERROR(Kosten!C42+Kosten!C43+Kosten!C44+Kosten!C45,0) | AI23: =IFERROR(Kosten!C42+Kosten!C43+Kosten!C44+Kosten!C45,0) | AJ23: =IFERROR(Kosten!C42+Kosten!C43+Kosten!C44+Kosten!C45,0) | AK23: =IFERROR(Kosten!C42+Kosten!C43+Kosten!C44+Kosten!C45,0)
A24: Verzekeringen en juridisch | B24: =IFERROR(Kosten!C49+Kosten!C50+Kosten!C51+Kosten!C52,0) | C24: =IFERROR(Kosten!C49+Kosten!C50+Kosten!C51+Kosten!C52,0) | D24: =IFERROR(Kosten!C49+Kosten!C50+Kosten!C51+Kosten!C52,0) | E24: =IFERROR(Kosten!C49+Kosten!C50+Kosten!C51+Kosten!C52,0) | F24: =IFERROR(Kosten!C49+Kosten!C50+Kosten!C51+Kosten!C52,0) | G24: =IFERROR(Kosten!C49+Kosten!C50+Kosten!C51+Kosten!C52,0) | H24: =IFERROR(Kosten!C49+Kosten!C50+Kosten!C51+Kosten!C52,0) | I24: =IFERROR(Kosten!C49+Kosten!C50+Kosten!C51+Kosten!C52,0) | J24: =IFERROR(Kosten!C49+Kosten!C50+Kosten!C51+Kosten!C52,0) | K24: =IFERROR(Kosten!C49+Kosten!C50+Kosten!C51+Kosten!C52,0) | L24: =IFERROR(Kosten!C49+Kosten!C50+Kosten!C51+Kosten!C52,0) | M24: =IFERROR(Kosten!C49+Kosten!C50+Kosten!C51+Kosten!C52,0) | N24: =IFERROR(Kosten!C49+Kosten!C50+Kosten!C51+Kosten!C52,0) | O24: =IFERROR(Kosten!C49+Kosten!C50+Kosten!C51+Kosten!C52,0) | P24: =IFERROR(Kosten!C49+Kosten!C50+Kosten!C51+Kosten!C52,0) | Q24: =IFERROR(Kosten!C49+Kosten!C50+Kosten!C51+Kosten!C52,0) | R24: =IFERROR(Kosten!C49+Kosten!C50+Kosten!C51+Kosten!C52,0) | S24: =IFERROR(Kosten!C49+Kosten!C50+Kosten!C51+Kosten!C52,0) | T24: =IFERROR(Kosten!C49+Kosten!C50+Kosten!C51+Kosten!C52,0) | U24: =IFERROR(Kosten!C49+Kosten!C50+Kosten!C51+Kosten!C52,0) | V24: =IFERROR(Kosten!C49+Kosten!C50+Kosten!C51+Kosten!C52,0) | W24: =IFERROR(Kosten!C49+Kosten!C50+Kosten!C51+Kosten!C52,0) | X24: =IFERROR(Kosten!C49+Kosten!C50+Kosten!C51+Kosten!C52,0) | Y24: =IFERROR(Kosten!C49+Kosten!C50+Kosten!C51+Kosten!C52,0) | Z24: =IFERROR(Kosten!C49+Kosten!C50+Kosten!C51+Kosten!C52,0) | AA24: =IFERROR(Kosten!C49+Kosten!C50+Kosten!C51+Kosten!C52,0) | AB24: =IFERROR(Kosten!C49+Kosten!C50+Kosten!C51+Kosten!C52,0) | AC24: =IFERROR(Kosten!C49+Kosten!C50+Kosten!C51+Kosten!C52,0) | AD24: =IFERROR(Kosten!C49+Kosten!C50+Kosten!C51+Kosten!C52,0) | AE24: =IFERROR(Kosten!C49+Kosten!C50+Kosten!C51+Kosten!C52,0) | AF24: =IFERROR(Kosten!C49+Kosten!C50+Kosten!C51+Kosten!C52,0) | AG24: =IFERROR(Kosten!C49+Kosten!C50+Kosten!C51+Kosten!C52,0) | AH24: =IFERROR(Kosten!C49+Kosten!C50+Kosten!C51+Kosten!C52,0) | AI24: =IFERROR(Kosten!C49+Kosten!C50+Kosten!C51+Kosten!C52,0) | AJ24: =IFERROR(Kosten!C49+Kosten!C50+Kosten!C51+Kosten!C52,0) | AK24: =IFERROR(Kosten!C49+Kosten!C50+Kosten!C51+Kosten!C52,0)
A25: Overige kosten | B25: =IFERROR(Kosten!C62+Kosten!C63+Kosten!C64+Kosten!C56+(Kosten!C57+Kosten!C58)*(B5+B6+B7)+Kosten!C65*SUM(B16:B24),0) | C25: =IFERROR(Kosten!C62+Kosten!C63+Kosten!C64+Kosten!C56+(Kosten!C57+Kosten!C58)*(C5+C6+C7)+Kosten!C65*SUM(C16:C24),0) | D25: =IFERROR(Kosten!C62+Kosten!C63+Kosten!C64+Kosten!C56+(Kosten!C57+Kosten!C58)*(D5+D6+D7)+Kosten!C65*SUM(D16:D24),0) | E25: =IFERROR(Kosten!C62+Kosten!C63+Kosten!C64+Kosten!C56+(Kosten!C57+Kosten!C58)*(E5+E6+E7)+Kosten!C65*SUM(E16:E24),0) | F25: =IFERROR(Kosten!C62+Kosten!C63+Kosten!C64+Kosten!C56+(Kosten!C57+Kosten!C58)*(F5+F6+F7)+Kosten!C65*SUM(F16:F24),0) | G25: =IFERROR(Kosten!C62+Kosten!C63+Kosten!C64+Kosten!C56+(Kosten!C57+Kosten!C58)*(G5+G6+G7)+Kosten!C65*SUM(G16:G24),0) | H25: =IFERROR(Kosten!C62+Kosten!C63+Kosten!C64+Kosten!C56+(Kosten!C57+Kosten!C58)*(H5+H6+H7)+Kosten!C65*SUM(H16:H24),0) | I25: =IFERROR(Kosten!C62+Kosten!C63+Kosten!C64+Kosten!C56+(Kosten!C57+Kosten!C58)*(I5+I6+I7)+Kosten!C65*SUM(I16:I24),0) | J25: =IFERROR(Kosten!C62+Kosten!C63+Kosten!C64+Kosten!C56+(Kosten!C57+Kosten!C58)*(J5+J6+J7)+Kosten!C65*SUM(J16:J24),0) | K25: =IFERROR(Kosten!C62+Kosten!C63+Kosten!C64+Kosten!C56+(Kosten!C57+Kosten!C58)*(K5+K6+K7)+Kosten!C65*SUM(K16:K24),0) | L25: =IFERROR(Kosten!C62+Kosten!C63+Kosten!C64+Kosten!C56+(Kosten!C57+Kosten!C58)*(L5+L6+L7)+Kosten!C65*SUM(L16:L24),0) | M25: =IFERROR(Kosten!C62+Kosten!C63+Kosten!C64+Kosten!C56+(Kosten!C57+Kosten!C58)*(M5+M6+M7)+Kosten!C65*SUM(M16:M24),0) | N25: =IFERROR(Kosten!C62+Kosten!C63+Kosten!C64+Kosten!C56+(Kosten!C57+Kosten!C58)*(N5+N6+N7)+Kosten!C65*SUM(N16:N24),0) | O25: =IFERROR(Kosten!C62+Kosten!C63+Kosten!C64+Kosten!C56+(Kosten!C57+Kosten!C58)*(O5+O6+O7)+Kosten!C65*SUM(O16:O24),0) | P25: =IFERROR(Kosten!C62+Kosten!C63+Kosten!C64+Kosten!C56+(Kosten!C57+Kosten!C58)*(P5+P6+P7)+Kosten!C65*SUM(P16:P24),0) | Q25: =IFERROR(Kosten!C62+Kosten!C63+Kosten!C64+Kosten!C56+(Kosten!C57+Kosten!C58)*(Q5+Q6+Q7)+Kosten!C65*SUM(Q16:Q24),0) | R25: =IFERROR(Kosten!C62+Kosten!C63+Kosten!C64+Kosten!C56+(Kosten!C57+Kosten!C58)*(R5+R6+R7)+Kosten!C65*SUM(R16:R24),0) | S25: =IFERROR(Kosten!C62+Kosten!C63+Kosten!C64+Kosten!C56+(Kosten!C57+Kosten!C58)*(S5+S6+S7)+Kosten!C65*SUM(S16:S24),0) | T25: =IFERROR(Kosten!C62+Kosten!C63+Kosten!C64+Kosten!C56+(Kosten!C57+Kosten!C58)*(T5+T6+T7)+Kosten!C65*SUM(T16:T24),0) | U25: =IFERROR(Kosten!C62+Kosten!C63+Kosten!C64+Kosten!C56+(Kosten!C57+Kosten!C58)*(U5+U6+U7)+Kosten!C65*SUM(U16:U24),0) | V25: =IFERROR(Kosten!C62+Kosten!C63+Kosten!C64+Kosten!C56+(Kosten!C57+Kosten!C58)*(V5+V6+V7)+Kosten!C65*SUM(V16:V24),0) | W25: =IFERROR(Kosten!C62+Kosten!C63+Kosten!C64+Kosten!C56+(Kosten!C57+Kosten!C58)*(W5+W6+W7)+Kosten!C65*SUM(W16:W24),0) | X25: =IFERROR(Kosten!C62+Kosten!C63+Kosten!C64+Kosten!C56+(Kosten!C57+Kosten!C58)*(X5+X6+X7)+Kosten!C65*SUM(X16:X24),0) | Y25: =IFERROR(Kosten!C62+Kosten!C63+Kosten!C64+Kosten!C56+(Kosten!C57+Kosten!C58)*(Y5+Y6+Y7)+Kosten!C65*SUM(Y16:Y24),0) | Z25: =IFERROR(Kosten!C62+Kosten!C63+Kosten!C64+Kosten!C56+(Kosten!C57+Kosten!C58)*(Z5+Z6+Z7)+Kosten!C65*SUM(Z16:Z24),0) | AA25: =IFERROR(Kosten!C62+Kosten!C63+Kosten!C64+Kosten!C56+(Kosten!C57+Kosten!C58)*(AA5+AA6+AA7)+Kosten!C65*SUM(AA16:AA24),0) | AB25: =IFERROR(Kosten!C62+Kosten!C63+Kosten!C64+Kosten!C56+(Kosten!C57+Kosten!C58)*(AB5+AB6+AB7)+Kosten!C65*SUM(AB16:AB24),0) | AC25: =IFERROR(Kosten!C62+Kosten!C63+Kosten!C64+Kosten!C56+(Kosten!C57+Kosten!C58)*(AC5+AC6+AC7)+Kosten!C65*SUM(AC16:AC24),0) | AD25: =IFERROR(Kosten!C62+Kosten!C63+Kosten!C64+Kosten!C56+(Kosten!C57+Kosten!C58)*(AD5+AD6+AD7)+Kosten!C65*SUM(AD16:AD24),0) | AE25: =IFERROR(Kosten!C62+Kosten!C63+Kosten!C64+Kosten!C56+(Kosten!C57+Kosten!C58)*(AE5+AE6+AE7)+Kosten!C65*SUM(AE16:AE24),0) | AF25: =IFERROR(Kosten!C62+Kosten!C63+Kosten!C64+Kosten!C56+(Kosten!C57+Kosten!C58)*(AF5+AF6+AF7)+Kosten!C65*SUM(AF16:AF24),0) | AG25: =IFERROR(Kosten!C62+Kosten!C63+Kosten!C64+Kosten!C56+(Kosten!C57+Kosten!C58)*(AG5+AG6+AG7)+Kosten!C65*SUM(AG16:AG24),0) | AH25: =IFERROR(Kosten!C62+Kosten!C63+Kosten!C64+Kosten!C56+(Kosten!C57+Kosten!C58)*(AH5+AH6+AH7)+Kosten!C65*SUM(AH16:AH24),0) | AI25: =IFERROR(Kosten!C62+Kosten!C63+Kosten!C64+Kosten!C56+(Kosten!C57+Kosten!C58)*(AI5+AI6+AI7)+Kosten!C65*SUM(AI16:AI24),0) | AJ25: =IFERROR(Kosten!C62+Kosten!C63+Kosten!C64+Kosten!C56+(Kosten!C57+Kosten!C58)*(AJ5+AJ6+AJ7)+Kosten!C65*SUM(AJ16:AJ24),0) | AK25: =IFERROR(Kosten!C62+Kosten!C63+Kosten!C64+Kosten!C56+(Kosten!C57+Kosten!C58)*(AK5+AK6+AK7)+Kosten!C65*SUM(AK16:AK24),0)
A26: TOTALE KOSTEN | B26: =IFERROR(SUM(B16:B25),0) | C26: =IFERROR(SUM(C16:C25),0) | D26: =IFERROR(SUM(D16:D25),0) | E26: =IFERROR(SUM(E16:E25),0) | F26: =IFERROR(SUM(F16:F25),0) | G26: =IFERROR(SUM(G16:G25),0) | H26: =IFERROR(SUM(H16:H25),0) | I26: =IFERROR(SUM(I16:I25),0) | ... AK26: =IFERROR(SUM(AK16:AK25),0)
A28: NETTO RESULTAAT | B28: =IFERROR(B13-B26,0) | C28: =IFERROR(C13-C26,0) | D28: =IFERROR(D13-D26,0) | E28: =IFERROR(E13-E26,0) | F28: =IFERROR(F13-F26,0) | G28: =IFERROR(G13-G26,0) | H28: =IFERROR(H13-H26,0) | I28: =IFERROR(I13-I26,0) | ... AK28: =IFERROR(AK13-AK26,0)
A29: Marge % | B29: =IFERROR(B28/B13,"") | C29: =IFERROR(C28/C13,"") | D29: =IFERROR(D28/D13,"") | E29: =IFERROR(E28/E13,"") | F29: =IFERROR(F28/F13,"") | G29: =IFERROR(G28/G13,"") | H29: =IFERROR(H28/H13,"") | I29: =IFERROR(I28/I13,"") | ... AK29: =IFERROR(AK28/AK13,"")
A30: Cumulatief resultaat | B30: =B28 | C30: =B30+C28 | D30: =C30+D28 | E30: =D30+E28 | F30: =E30+F28 | G30: =F30+G28 | H30: =G30+H28 | I30: =H30+I28 | J30: =I30+J28 | ... AK30: =AJ30+AK28
A33: JAARTOTALEN
B34: 2026 (5 mnd) | C34: 2027 | D34: 2028 | E34: 2029 (7 mnd)
A35: Omzet | B35: =B13+C13+D13+E13+F13 | C35: =G13+H13+I13+J13+K13+L13+M13+N13+O13+P13+Q13+R13 | D35: =S13+T13+U13+V13+W13+X13+Y13+Z13+AA13+AB13+AC13+AD13 | E35: =AE13+AF13+AG13+AH13+AI13+AJ13+AK13
A36: Kosten | B36: =B26+C26+D26+E26+F26 | C36: =G26+H26+I26+J26+K26+L26+M26+N26+O26+P26+Q26+R26 | D36: =S26+T26+U26+V26+W26+X26+Y26+Z26+AA26+AB26+AC26+AD26 | E36: =AE26+AF26+AG26+AH26+AI26+AJ26+AK26
A37: Resultaat | B37: =B28+C28+D28+E28+F28 | C37: =G28+H28+I28+J28+K28+L28+M28+N28+O28+P28+Q28+R28 | D37: =S28+T28+U28+V28+W28+X28+Y28+Z28+AA28+AB28+AC28+AD28 | E37: =AE28+AF28+AG28+AH28+AI28+AJ28+AK28

Sheet Cashflow
A1: HES Cashflow 2026-2029
A3: Startkapitaal (EUR) | B3: =Aannames!B5
B5: Aug '26 | C5: Sep '26 | D5: Okt '26 | E5: Nov '26 | F5: Dec '26 | G5: Jan '27 | H5: Feb '27 | I5: Mrt '27 | J5: Apr '27 | K5: Mei '27 | L5: Jun '27 | M5: Jul '27 | N5: Aug '27 | O5: Sep '27 | P5: Okt '27 | Q5: Nov '27 | R5: Dec '27 | S5: Jan '28 | T5: Feb '28 | U5: Mrt '28 | V5: Apr '28 | W5: Mei '28 | X5: Jun '28 | Y5: Jul '28 | Z5: Aug '28 | AA5: Sep '28 | AB5: Okt '28 | AC5: Nov '28 | AD5: Dec '28 | AE5: Jan '29 | AF5: Feb '29 | AG5: Mrt '29 | AH5: Apr '29 | AI5: Mei '29 | AJ5: Jun '29 | AK5: Jul '29
A6: INKOMSTEN
A7: Batterijsystemen | B7: =Budget!B5 | C7: =Budget!C5 | D7: =Budget!D5 | E7: =Budget!E5 | F7: =Budget!F5 | G7: =Budget!G5 | H7: =Budget!H5 | I7: =Budget!I5 | ... AK7: =Budget!AK5
A8: AC Laadpalen | B8: =Budget!B6 | C8: =Budget!C6 | D8: =Budget!D6 | E8: =Budget!E6 | F8: =Budget!F6 | G8: =Budget!G6 | H8: =Budget!H6 | I8: =Budget!I6 | ... AK8: =Budget!AK6
A9: DC Snelladers | B9: =Budget!B7 | C9: =Budget!C7 | D9: =Budget!D7 | E9: =Budget!E7 | F9: =Budget!F7 | G9: =Budget!G7 | H9: =Budget!H7 | I9: =Budget!I7 | ... AK9: =Budget!AK7
A10: Laadopbrengst kWh | B10: =Budget!B8 | C10: =Budget!C8 | D10: =Budget!D8 | E10: =Budget!E8 | F10: =Budget!F8 | G10: =Budget!G8 | H10: =Budget!H8 | I10: =Budget!I8 | ... AK10: =Budget!AK8
A11: Support en onderhoud | B11: =Budget!B9 | C11: =Budget!C9 | D11: =Budget!D9 | E11: =Budget!E9 | F11: =Budget!F9 | G11: =Budget!G9 | H11: =Budget!H9 | I11: =Budget!I9 | ... AK11: =Budget!AK9
A12: Onderdelen | B12: =Budget!B10 | C12: =Budget!C10 | D12: =Budget!D10 | E12: =Budget!E10 | F12: =Budget!F10 | G12: =Budget!G10 | H12: =Budget!H10 | I12: =Budget!I10 | ... AK12: =Budget!AK10
A13: Kickback zonnepanelen | B13: =Budget!B11 | C13: =Budget!C11 | D13: =Budget!D11 | E13: =Budget!E11 | F13: =Budget!F11 | G13: =Budget!G11 | H13: =Budget!H11 | I13: =Budget!I11 | ... AK13: =Budget!AK11
A14: Extra garantie | B14: =Budget!B12 | C14: =Budget!C12 | D14: =Budget!D12 | E14: =Budget!E12 | F14: =Budget!F12 | G14: =Budget!G12 | H14: =Budget!H12 | I14: =Budget!I12 | ... AK14: =Budget!AK12
A15: TOTALE INKOMSTEN | B15: =SUM(B7:B14) | C15: =SUM(C7:C14) | D15: =SUM(D7:D14) | E15: =SUM(E7:E14) | F15: =SUM(F7:F14) | G15: =SUM(G7:G14) | H15: =SUM(H7:H14) | I15: =SUM(I7:I14) | ... AK15: =SUM(AK7:AK14)
A17: UITGAVEN
A18: Inkoop batterijen | B18: =Budget!B16 | C18: =Budget!C16 | D18: =Budget!D16 | E18: =Budget!E16 | F18: =Budget!F16 | G18: =Budget!G16 | H18: =Budget!H16 | I18: =Budget!I16 | ... AK18: =Budget!AK16
A19: Inkoop AC laders | B19: =Budget!B17 | C19: =Budget!C17 | D19: =Budget!D17 | E19: =Budget!E17 | F19: =Budget!F17 | G19: =Budget!G17 | H19: =Budget!H17 | I19: =Budget!I17 | ... AK19: =Budget!AK17
A20: Inkoop DC laders | B20: =Budget!B18 | C20: =Budget!C18 | D20: =Budget!D18 | E20: =Budget!E18 | F20: =Budget!F18 | G20: =Budget!G18 | H20: =Budget!H18 | I20: =Budget!I18 | ... AK20: =Budget!AK18
A21: Installatie en logistiek | B21: =Budget!B19 | C21: =Budget!C19 | D21: =Budget!D19 | E21: =Budget!E19 | F21: =Budget!F19 | G21: =Budget!G19 | H21: =Budget!H19 | I21: =Budget!I19 | ... AK21: =Budget!AK19
A22: Personeel | B22: =Budget!B20 | C22: =Budget!C20 | D22: =Budget!D20 | E22: =Budget!E20 | F22: =Budget!F20 | G22: =Budget!G20 | H22: =Budget!H20 | I22: =Budget!I20 | ... AK22: =Budget!AK20
A23: Marketing en sales | B23: =Budget!B21 | C23: =Budget!C21 | D23: =Budget!D21 | E23: =Budget!E21 | F23: =Budget!F21 | G23: =Budget!G21 | H23: =Budget!H21 | I23: =Budget!I21 | ... AK23: =Budget!AK21
A24: Kantoor en operations | B24: =Budget!B22 | C24: =Budget!C22 | D24: =Budget!D22 | E24: =Budget!E22 | F24: =Budget!F22 | G24: =Budget!G22 | H24: =Budget!H22 | I24: =Budget!I22 | ... AK24: =Budget!AK22
A25: Software, tools en IT | B25: =Budget!B23 | C25: =Budget!C23 | D25: =Budget!D23 | E25: =Budget!E23 | F25: =Budget!F23 | G25: =Budget!G23 | H25: =Budget!H23 | I25: =Budget!I23 | ... AK25: =Budget!AK23
A26: Verzekeringen | B26: =Budget!B24 | C26: =Budget!C24 | D26: =Budget!D24 | E26: =Budget!E24 | F26: =Budget!F24 | G26: =Budget!G24 | H26: =Budget!H24 | I26: =Budget!I24 | ... AK26: =Budget!AK24
A27: Onvoorzien | B27: =Budget!B25 | C27: =Budget!C25 | D27: =Budget!D25 | E27: =Budget!E25 | F27: =Budget!F25 | G27: =Budget!G25 | H27: =Budget!H25 | I27: =Budget!I25 | ... AK27: =Budget!AK25
A28: TOTALE UITGAVEN | B28: =SUM(B18:B27) | C28: =SUM(C18:C27) | D28: =SUM(D18:D27) | E28: =SUM(E18:E27) | F28: =SUM(F18:F27) | G28: =SUM(G18:G27) | H28: =SUM(H18:H27) | I28: =SUM(I18:I27) | ... AK28: =SUM(AK18:AK27)
A30: BTW
A31: BTW op verkopen | B31: =Aannames!B48*B15 | C31: =Aannames!B48*C15 | D31: =Aannames!B48*D15 | E31: =Aannames!B48*E15 | F31: =Aannames!B48*F15 | G31: =Aannames!B48*G15 | H31: =Aannames!B48*H15 | I31: =Aannames!B48*I15 | J31: =Aannames!B48*J15 | K31: =Aannames!B48*K15 | L31: =Aannames!B48*L15 | M31: =Aannames!B48*M15 | N31: =Aannames!B48*N15 | O31: =Aannames!B48*O15 | P31: =Aannames!B48*P15 | Q31: =Aannames!B48*Q15 | R31: =Aannames!B48*R15 | S31: =Aannames!B48*S15 | T31: =Aannames!B48*T15 | U31: =Aannames!B48*U15 | V31: =Aannames!B48*V15 | W31: =Aannames!B48*W15 | X31: =Aannames!B48*X15 | Y31: =Aannames!B48*Y15 | Z31: =Aannames!B48*Z15 | AA31: =Aannames!B48*AA15 | AB31: =Aannames!B48*AB15 | AC31: =Aannames!B48*AC15 | AD31: =Aannames!B48*AD15 | AE31: =Aannames!B48*AE15 | AF31: =Aannames!B48*AF15 | AG31: =Aannames!B48*AG15 | AH31: =Aannames!B48*AH15 | AI31: =Aannames!B48*AI15 | AJ31: =Aannames!B48*AJ15 | AK31: =Aannames!B48*AK15
A32: BTW op inkopen (hardware) | B32: =Aannames!B48*(B18+B19+B20+B21) | C32: =Aannames!B48*(C18+C19+C20+C21) | D32: =Aannames!B48*(D18+D19+D20+D21) | E32: =Aannames!B48*(E18+E19+E20+E21) | F32: =Aannames!B48*(F18+F19+F20+F21) | G32: =Aannames!B48*(G18+G19+G20+G21) | H32: =Aannames!B48*(H18+H19+H20+H21) | I32: =Aannames!B48*(I18+I19+I20+I21) | J32: =Aannames!B48*(J18+J19+J20+J21) | K32: =Aannames!B48*(K18+K19+K20+K21) | L32: =Aannames!B48*(L18+L19+L20+L21) | M32: =Aannames!B48*(M18+M19+M20+M21) | N32: =Aannames!B48*(N18+N19+N20+N21) | O32: =Aannames!B48*(O18+O19+O20+O21) | P32: =Aannames!B48*(P18+P19+P20+P21) | Q32: =Aannames!B48*(Q18+Q19+Q20+Q21) | R32: =Aannames!B48*(R18+R19+R20+R21) | S32: =Aannames!B48*(S18+S19+S20+S21) | T32: =Aannames!B48*(T18+T19+T20+T21) | U32: =Aannames!B48*(U18+U19+U20+U21) | V32: =Aannames!B48*(V18+V19+V20+V21) | W32: =Aannames!B48*(W18+W19+W20+W21) | X32: =Aannames!B48*(X18+X19+X20+X21) | Y32: =Aannames!B48*(Y18+Y19+Y20+Y21) | Z32: =Aannames!B48*(Z18+Z19+Z20+Z21) | AA32: =Aannames!B48*(AA18+AA19+AA20+AA21) | AB32: =Aannames!B48*(AB18+AB19+AB20+AB21) | AC32: =Aannames!B48*(AC18+AC19+AC20+AC21) | AD32: =Aannames!B48*(AD18+AD19+AD20+AD21) | AE32: =Aannames!B48*(AE18+AE19+AE20+AE21) | AF32: =Aannames!B48*(AF18+AF19+AF20+AF21) | AG32: =Aannames!B48*(AG18+AG19+AG20+AG21) | AH32: =Aannames!B48*(AH18+AH19+AH20+AH21) | AI32: =Aannames!B48*(AI18+AI19+AI20+AI21) | AJ32: =Aannames!B48*(AJ18+AJ19+AJ20+AJ21) | AK32: =Aannames!B48*(AK18+AK19+AK20+AK21)
A33: BTW saldo (af te dragen) | B33: =B31-B32 | C33: =C31-C32 | D33: =D31-D32 | E33: =E31-E32 | F33: =F31-F32 | G33: =G31-G32 | H33: =H31-H32 | I33: =I31-I32 | ... AK33: =AK31-AK32
A35: NETTO CASHFLOW | B35: =B15-B28-B33 | C35: =C15-C28-C33 | D35: =D15-D28-D33 | E35: =E15-E28-E33 | F35: =F15-F28-F33 | G35: =G15-G28-G33 | H35: =H15-H28-H33 | I35: =I15-I28-I33 | ... AK35: =AK15-AK28-AK33
A36: Cumulatieve cashflow | B36: =B3+B35 | C36: =B36+C35 | D36: =C36+D35 | E36: =D36+E35 | F36: =E36+F35 | G36: =F36+G35 | H36: =G36+H35 | I36: =H36+I35 | J36: =I36+J35 | ... AK36: =AJ36+AK35
A37: Kaspositie einde maand | B37: =B36 | C37: =C36 | D37: =D36 | E37: =E36 | F37: =F36 | G37: =G36 | H37: =H36 | I37: =I36 | ... AK37: =AK36

Sheet Dashboard
A1: HES Dashboard 2026-2029
A3: Kerncijfers
A4: Omzet 2026 (5 mnd) | B4: =Budget!B13+C13+D13+E13+F13
A5: Kosten 2026 (5 mnd) | B5: =Budget!B26+C26+D26+E26+F26
A6: Resultaat 2026 (5 mnd) | B6: =Budget!B28+C28+D28+E28+F28
A7: Omzet 2027 | B7: =Budget!G13+H13+I13+J13+K13+L13+M13+N13+O13+P13+Q13+R13
A8: Kosten 2027 | B8: =Budget!G26+H26+I26+J26+K26+L26+M26+N26+O26+P26+Q26+R26
A9: Resultaat 2027 | B9: =Budget!G28+H28+I28+J28+K28+L28+M28+N28+O28+P28+Q28+R28
A10: Omzet 2028 | B10: =Budget!S13+T13+U13+V13+W13+X13+Y13+Z13+AA13+AB13+AC13+AD13
A11: Kosten 2028 | B11: =Budget!S26+T26+U26+V26+W26+X26+Y26+Z26+AA26+AB26+AC26+AD26
A12: Resultaat 2028 | B12: =Budget!S28+T28+U28+V28+W28+X28+Y28+Z28+AA28+AB28+AC28+AD28
A13: Omzet 2029 (7 mnd) | B13: =Budget!AE13+AF13+AG13+AH13+AI13+AJ13+AK13
