Workbook

Sheet Budget
A1: HES Budget 2026-2027
A2: Hospitality Energy Solutions — 12-maanden prognose
B4: Aug '26 | C4: Sep '26 | D4: Okt '26 | E4: Nov '26 | F4: Dec '26 | G4: Jan '27 | H4: Feb '27 | I4: Mrt '27 | J4: Apr '27 | K4: Mei '27 | L4: Jun '27 | M4: Jul '27
A5: OMZET
A6: Batterijsystemen (ESS) | B6: =H49*1 | C6: =H49*1 | D6: =H49*1 | E6: =H49*2 | F6: =H49*2 | G6: =H49*2 | H6: =H49*2 | I6: =H49*2 | J6: =H49*3 | K6: =H49*3 | L6: =H49*3 | M6: =H49*3
A7: AC Laadpalen | B7: =H50*4 | C7: =H50*5 | D7: =H50*6 | E7: =H50*7 | F7: =H50*8 | G7: =H50*9 | H7: =H50*10 | I7: =H50*10 | J7: =H50*12 | K7: =H50*12 | L7: =H50*14 | M7: =H50*14
A8: DC Snelladers | B8: =H51*0 | C8: =H51*1 | D8: =H51*0 | E8: =H51*1 | F8: =H51*0 | G8: =H51*1 | H8: =H51*1 | I8: =H51*1 | J8: =H51*1 | K8: =H51*2 | L8: =H51*1 | M8: =H51*2
A9: Laadopbrengst (EUR/kWh) | B9: =(B7+B8)*$H$54*$H$53 | C9: =(C7+C8)*$H$54*$H$53 | D9: =(D7+D8)*$H$54*$H$53 | E9: =(E7+E8)*$H$54*$H$53 | F9: =(F7+F8)*$H$54*$H$53 | G9: =(G7+G8)*$H$54*$H$53 | H9: =(H7+H8)*$H$54*$H$53 | I9: =(I7+I8)*$H$54*$H$53 | ... M9: =(M7+M8)*$H$54*$H$53
A10: Support & onderhoud | B10: =(B6+$H$56)*$H$55 | C10: =(C6+$H$56)*$H$55 | D10: =(D6+$H$56)*$H$55 | E10: =(E6+$H$56)*$H$55 | F10: =(F6+$H$56)*$H$55 | G10: =(G6+$H$56)*$H$55 | H10: =(H6+$H$56)*$H$55 | I10: =(I6+$H$56)*$H$55 | ... M10: =(M6+$H$56)*$H$55
A11: Onderdelen & accessoires | B11: =0.03*(B6+B7+B8) | C11: =0.03*(C6+C7+C8) | D11: =0.03*(D6+D7+D8) | E11: =0.03*(E6+E7+E8) | F11: =0.03*(F6+F7+F8) | G11: =0.03*(G6+G7+G8) | H11: =0.03*(H6+H7+H8) | I11: =0.03*(I6+I7+I8) | ... M11: =0.03*(M6+M7+M8)
A12: Kickback zonnepanelen | B12: =$H$58*$H$57*$H$59 | C12: =$H$58*$H$57*$H$59 | D12: =$H$58*$H$57*$H$59 | E12: =$H$58*$H$57*$H$59 | F12: =$H$58*$H$57*$H$59 | G12: =$H$58*$H$57*$H$59 | H12: =$H$58*$H$57*$H$59 | I12: =$H$58*$H$57*$H$59 | ... M12: =$H$58*$H$57*$H$59
A13: Extra garantie | B13: =B6*$H$60*$H$61 | C13: =C6*$H$60*$H$61 | D13: =D6*$H$60*$H$61 | E13: =E6*$H$60*$H$61 | F13: =F6*$H$60*$H$61 | G13: =G6*$H$60*$H$61 | H13: =H6*$H$60*$H$61 | I13: =I6*$H$60*$H$61 | ... M13: =M6*$H$60*$H$61
A14: TOTALE OMZET | B14: =SUM(B6:B13) | C14: =SUM(C6:C13) | D14: =SUM(D6:D13) | E14: =SUM(E6:E13) | F14: =SUM(F6:F13) | G14: =SUM(G6:G13) | H14: =SUM(H6:H13) | I14: =SUM(I6:I13) | ... M14: =SUM(M6:M13)
A16: KOSTEN
A17: Inkoop batterijsystemen | B17: =0.68*B6 | C17: =0.68*C6 | D17: =0.68*D6 | E17: =0.68*E6 | F17: =0.68*F6 | G17: =0.68*G6 | H17: =0.68*H6 | I17: =0.68*I6 | ... M17: =0.68*M6
A18: Inkoop AC laadpalen | B18: =0.59*B7 | C18: =0.59*C7 | D18: =0.59*D7 | E18: =0.59*E7 | F18: =0.59*F7 | G18: =0.59*G7 | H18: =0.59*H7 | I18: =0.59*I7 | ... M18: =0.59*M7
A19: Inkoop DC snelladers | B19: =0.67*B8 | C19: =0.67*C8 | D19: =0.67*D8 | E19: =0.67*E8 | F19: =0.67*F8 | G19: =0.67*G8 | H19: =0.67*H8 | I19: =0.67*I8 | ... M19: =0.67*M8
A20: Installatie & logistiek | B20: =0.12*(B6+B7+B8) | C20: =0.12*(C6+C7+C8) | D20: =0.12*(D6+D7+D8) | E20: =0.12*(E6+E7+E8) | F20: =0.12*(F6+F7+F8) | G20: =0.12*(G6+G7+G8) | H20: =0.12*(H6+H7+H8) | I20: =0.12*(I6+I7+I8) | ... M20: =0.12*(M6+M7+M8)
A21: Personeel | B21: 8500 | C21: 8500 | D21: 10000 | E21: 10000 | F21: 10000 | G21: 12000 | H21: 12000 | I21: 12000 | J21: 14000 | K21: 14000 | L21: 14000 | M21: 16000
A22: Marketing & sales | B22: 4000 | C22: 4000 | D22: 4500 | E22: 5000 | F22: 5000 | G22: 5000 | H22: 5500 | I22: 5500 | J22: 6000 | K22: 6000 | L22: 6000 | M22: 6000
A23: Kantoor & operations | B23: 2500 | C23: 2500 | D23: 2500 | E23: 2500 | F23: 2500 | G23: 2500 | H23: 2500 | I23: 2500 | J23: 2500 | K23: 2500 | L23: 2500 | M23: 2500
A24: Software, tools & IT | B24: 1000 | C24: 1000 | D24: 1000 | E24: 1000 | F24: 1000 | G24: 1000 | H24: 1000 | I24: 1000 | J24: 1000 | K24: 1000 | L24: 1000 | M24: 1000
A25: Verzekeringen & garantie | B25: 1500 | C25: 1500 | D25: 1500 | E25: 1500 | F25: 1500 | G25: 1500 | H25: 1500 | I25: 1500 | J25: 1500 | K25: 1500 | L25: 1500 | M25: 1500
A26: Onvoorzien (5%) | B26: =0.05*SUM(B17:B25) | C26: =0.05*SUM(C17:C25) | D26: =0.05*SUM(D17:D25) | E26: =0.05*SUM(E17:E25) | F26: =0.05*SUM(F17:F25) | G26: =0.05*SUM(G17:G25) | H26: =0.05*SUM(H17:H25) | I26: =0.05*SUM(I17:I25) | ... M26: =0.05*SUM(M17:M25)
A27: TOTALE KOSTEN | B27: =SUM(B17:B26) | C27: =SUM(C17:C26) | D27: =SUM(D17:D26) | E27: =SUM(E17:E26) | F27: =SUM(F17:F26) | G27: =SUM(G17:G26) | H27: =SUM(H17:H26) | I27: =SUM(I17:I26) | ... M27: =SUM(M17:M26)
A29: NETTO RESULTAAT | B29: =B14-B27 | C29: =C14-C27 | D29: =D14-D27 | E29: =E14-E27 | F29: =F14-F27 | G29: =G14-G27 | H29: =H14-H27 | I29: =I14-I27 | ... M29: =M14-M27
A30: Marge % | B30: =IFERROR(B29/B14,0) | C30: =IFERROR(C29/C14,0) | D30: =IFERROR(D29/D14,0) | E30: =IFERROR(E29/E14,0) | F30: =IFERROR(F29/F14,0) | G30: =IFERROR(G29/G14,0) | H30: =IFERROR(H29/H14,0) | I30: =IFERROR(I29/I14,0) | ... M30: =IFERROR(M29/M14,0)
A31: Cumulatief resultaat | B31: =B29 | C31: =B31+C29 | D31: =C31+D29 | E31: =D31+E29 | F31: =E31+F29 | G31: =F31+G29 | H31: =G31+H29 | I31: =H31+I29 | J31: =I31+J29 | ... M31: =L31+M29
A48: AANNAMES (gele cellen = zelf aanpassen)
A49: Prijs batterijsysteem (gem.) | B49: 85000
A50: Prijs AC laadpaal (gem.) | B50: 3200
A51: Prijs DC snellader (gem.) | B51: 42000
A52: — Lege regel —
A53: Laadopbrengst per kWh (EUR) | B53: 0.08
A54: Gem. kWh per laadpaal/maand | B54: 3000
A55: Support fee per klant/maand (EUR) | B55: 750
A56: Start aantal actieve klanten | B56: 2
A57: Kickback zon (%) | B57: 0.08
A58: Gem. zon-installatie waarde (EUR) | B58: 55000
A59: Aantal zon-projecten per maand | B59: 0.5
...

Sheet Dashboard
A1: HES KPI Dashboard
A3: Kerncijfers 12 maanden
A4: Totale omzet (12 mnd) | B4: =SUM(Budget!B14:M14)
A5: Totale kosten (12 mnd) | B5: =SUM(Budget!B27:M27)
A6: Netto resultaat (12 mnd) | B6: =SUM(Budget!B29:M29)
A7: Gemiddelde marge | B7: =AVERAGE(Budget!B30:M30)
A8: Batterijen verkocht (totaal) | B8: =SUM(Budget!B6:M6)/Budget!H49
A9: AC Laders verkocht (totaal) | B9: =SUM(Budget!B7:M7)/Budget!H50
A10: DC Snelladers verkocht (totaal) | B10: =SUM(Budget!B8:M8)/Budget!H51
A13: Hoe te gebruiken
A14: Pas de gele cellen in het Budget-tabblad aan om scenario's door te rekenen
A15: Alle formules werken automatisch door
A16: Importeer in Google Sheets: Bestand → Importeren → Uploaden
A17: De marge verbetert naarmate het klantenbestand groeit (support is recurring)

Sheet Verkoopprognose
A1: VERKOOPPROGNOSE 2026-2027
A2: Gele cellen = zelf invullen. Totaal wordt automatisch berekend.
A4: 1. BATTERIJSYSTEMEN (ESS)
A5: # | B5: Maand | C5: Aantal | D5: Prijs per stuk | E5: Totaal
A6: 1 | B6: Aug '26 | C6: 1 | D6: 85000 | E6: =C6*D6
A7: 2 | B7: Sep '26 | C7: 1 | D7: 85000 | E7: =C7*D7
A8: 3 | B8: Okt '26 | C8: 1 | D8: 85000 | E8: =C8*D8
A9: 4 | B9: Nov '26 | C9: 2 | D9: 85000 | E9: =C9*D9
A10: 5 | B10: Dec '26 | C10: 2 | D10: 85000 | E10: =C10*D10
A11: 6 | B11: Jan '27 | C11: 2 | D11: 85000 | E11: =C11*D11
A12: 7 | B12: Feb '27 | C12: 2 | D12: 85000 | E12: =C12*D12
A13: 8 | B13: Mrt '27 | C13: 2 | D13: 85000 | E13: =C13*D13
A14: 9 | B14: Apr '27 | C14: 3 | D14: 85000 | E14: =C14*D14
A15: 10 | B15: Mei '27 | C15: 3 | D15: 85000 | E15: =C15*D15
A16: 11 | B16: Jun '27 | C16: 3 | D16: 85000 | E16: =C16*D16
A17: 12 | B17: Jul '27 | C17: 3 | D17: 85000 | E17: =C17*D17
B18: TOTAAL | C18: =SUM(C6:C17) | E18: =SUM(E6:E17)
A20: 2. AC LAADPALEN
A21: # | B21: Maand | C21: Aantal | D21: Prijs per stuk | E21: Totaal
A22: 1 | B22: Aug '26 | C22: 4 | D22: 3200 | E22: =C22*D22
A23: 2 | B23: Sep '26 | C23: 5 | D23: 3200 | E23: =C23*D23
A24: 3 | B24: Okt '26 | C24: 6 | D24: 3200 | E24: =C24*D24
A25: 4 | B25: Nov '26 | C25: 7 | D25: 3200 | E25: =C25*D25
A26: 5 | B26: Dec '26 | C26: 8 | D26: 3200 | E26: =C26*D26
A27: 6 | B27: Jan '27 | C27: 9 | D27: 3200 | E27: =C27*D27
A28: 7 | B28: Feb '27 | C28: 10 | D28: 3200 | E28: =C28*D28
A29: 8 | B29: Mrt '27 | C29: 10 | D29: 3200 | E29: =C29*D29
A30: 9 | B30: Apr '27 | C30: 12 | D30: 3200 | E30: =C30*D30
A31: 10 | B31: Mei '27 | C31: 12 | D31: 3200 | E31: =C31*D31
A32: 11 | B32: Jun '27 | C32: 14 | D32: 3200 | E32: =C32*D32
A33: 12 | B33: Jul '27 | C33: 14 | D33: 3200 | E33: =C33*D33
B34: TOTAAL | C34: =SUM(C22:C33) | E34: =SUM(E22:E33)
A36: 3. DC SNELLADERS
A37: # | B37: Maand | C37: Aantal | D37: Prijs per stuk | E37: Totaal
A38: 1 | B38: Aug '26 | C38: 0 | D38: 42000 | E38: =C38*D38
A39: 2 | B39: Sep '26 | C39: 1 | D39: 42000 | E39: =C39*D39
A40: 3 | B40: Okt '26 | C40: 0 | D40: 42000 | E40: =C40*D40
A41: 4 | B41: Nov '26 | C41: 1 | D41: 42000 | E41: =C41*D41
A42: 5 | B42: Dec '26 | C42: 0 | D42: 42000 | E42: =C42*D42
A43: 6 | B43: Jan '27 | C43: 1 | D43: 42000 | E43: =C43*D43
...

Sheet Cashflow
A1: HES Cashflow Prognose 2026-2027
A2: Alle bedragen in EUR — gele cellen = zelf aanpassen
A4: Startkapitaal | B4: 100000 | C4: ← Pas aan naar jullie startbedrag
B6: Aug '26 | C6: Sep '26 | D6: Okt '26 | E6: Nov '26 | F6: Dec '26 | G6: Jan '27 | H6: Feb '27 | I6: Mrt '27 | J6: Apr '27 | K6: Mei '27 | L6: Jun '27 | M6: Jul '27
A7: INKOMSTEN
A8: Batterijsystemen | B8: ='Verkoopprognose'!E18 | C8: ='Verkoopprognose'!E18 | D8: ='Verkoopprognose'!E18 | E8: ='Verkoopprognose'!E18 | F8: ='Verkoopprognose'!E18 | G8: ='Verkoopprognose'!E18 | H8: ='Verkoopprognose'!E18 | I8: ='Verkoopprognose'!E18 | J8: ='Verkoopprognose'!E18 | K8: ='Verkoopprognose'!E18 | L8: ='Verkoopprognose'!E18 | M8: ='Verkoopprognose'!E18
A9: AC Laadpalen | B9: ='Verkoopprognose'!E36 | C9: ='Verkoopprognose'!E36 | D9: ='Verkoopprognose'!E36 | E9: ='Verkoopprognose'!E36 | F9: ='Verkoopprognose'!E36 | G9: ='Verkoopprognose'!E36 | H9: ='Verkoopprognose'!E36 | I9: ='Verkoopprognose'!E36 | J9: ='Verkoopprognose'!E36 | K9: ='Verkoopprognose'!E36 | L9: ='Verkoopprognose'!E36 | M9: ='Verkoopprognose'!E36
A10: DC Snelladers | B10: ='Verkoopprognose'!E54 | C10: ='Verkoopprognose'!E54 | D10: ='Verkoopprognose'!E54 | E10: ='Verkoopprognose'!E54 | F10: ='Verkoopprognose'!E54 | G10: ='Verkoopprognose'!E54 | H10: ='Verkoopprognose'!E54 | I10: ='Verkoopprognose'!E54 | J10: ='Verkoopprognose'!E54 | K10: ='Verkoopprognose'!E54 | L10: ='Verkoopprognose'!E54 | M10: ='Verkoopprognose'!E54
A11: Laadopbrengst kWh | B11: =Budget!B9 | C11: =Budget!C9 | D11: =Budget!D9 | E11: =Budget!E9 | F11: =Budget!F9 | G11: =Budget!G9 | H11: =Budget!H9 | I11: =Budget!I9 | ... M11: =Budget!M9
A12: Support & onderhoud | B12: =Budget!B10 | C12: =Budget!C10 | D12: =Budget!D10 | E12: =Budget!E10 | F12: =Budget!F10 | G12: =Budget!G10 | H12: =Budget!H10 | I12: =Budget!I10 | ... M12: =Budget!M10
A13: Onderdelen | B13: =Budget!B11 | C13: =Budget!C11 | D13: =Budget!D11 | E13: =Budget!E11 | F13: =Budget!F11 | G13: =Budget!G11 | H13: =Budget!H11 | I13: =Budget!I11 | ... M13: =Budget!M11
A14: Kickback zonnepanelen | B14: ='Verkoopprognose'!E90 | C14: ='Verkoopprognose'!E90 | D14: ='Verkoopprognose'!E90 | E14: ='Verkoopprognose'!E90 | F14: ='Verkoopprognose'!E90 | G14: ='Verkoopprognose'!E90 | H14: ='Verkoopprognose'!E90 | I14: ='Verkoopprognose'!E90 | J14: ='Verkoopprognose'!E90 | K14: ='Verkoopprognose'!E90 | L14: ='Verkoopprognose'!E90 | M14: ='Verkoopprognose'!E90
A15: Extra garantie | B15: ='Verkoopprognose'!E108 | C15: ='Verkoopprognose'!E108 | D15: ='Verkoopprognose'!E108 | E15: ='Verkoopprognose'!E108 | F15: ='Verkoopprognose'!E108 | G15: ='Verkoopprognose'!E108 | H15: ='Verkoopprognose'!E108 | I15: ='Verkoopprognose'!E108 | J15: ='Verkoopprognose'!E108 | K15: ='Verkoopprognose'!E108 | L15: ='Verkoopprognose'!E108 | M15: ='Verkoopprognose'!E108
A16: TOTALE INKOMSTEN | B16: =SUM(B8:B15) | C16: =SUM(C8:C15) | D16: =SUM(D8:D15) | E16: =SUM(E8:E15) | F16: =SUM(F8:F15) | G16: =SUM(G8:G15) | H16: =SUM(H8:H15) | I16: =SUM(I8:I15) | ... M16: =SUM(M8:M15)
A18: UITGAVEN
A19: Inkoop batterijen | B19: =Budget!B17 | C19: =Budget!C17 | D19: =Budget!D17 | E19: =Budget!E17 | F19: =Budget!F17 | G19: =Budget!G17 | H19: =Budget!H17 | I19: =Budget!I17 | ... M19: =Budget!M17
A20: Inkoop AC laders | B20: =Budget!B18 | C20: =Budget!C18 | D20: =Budget!D18 | E20: =Budget!E18 | F20: =Budget!F18 | G20: =Budget!G18 | H20: =Budget!H18 | I20: =Budget!I18 | ... M20: =Budget!M18
A21: Inkoop DC snelladers | B21: =Budget!B19 | C21: =Budget!C19 | D21: =Budget!D19 | E21: =Budget!E19 | F21: =Budget!F19 | G21: =Budget!G19 | H21: =Budget!H19 | I21: =Budget!I19 | ... M21: =Budget!M19
A22: Installatie & logistiek | B22: =Budget!B20 | C22: =Budget!C20 | D22: =Budget!D20 | E22: =Budget!E20 | F22: =Budget!F20 | G22: =Budget!G20 | H22: =Budget!H20 | I22: =Budget!I20 | ... M22: =Budget!M20
A23: Personeel | B23: =Budget!B21 | C23: =Budget!C21 | D23: =Budget!D21 | E23: =Budget!E21 | F23: =Budget!F21 | G23: =Budget!G21 | H23: =Budget!H21 | I23: =Budget!I21 | ... M23: =Budget!M21
A24: Marketing & sales | B24: =Budget!B22 | C24: =Budget!C22 | D24: =Budget!D22 | E24: =Budget!E22 | F24: =Budget!F22 | G24: =Budget!G22 | H24: =Budget!H22 | I24: =Budget!I22 | ... M24: =Budget!M22
A25: Kantoor & operations | B25: =Budget!B23 | C25: =Budget!C23 | D25: =Budget!D23 | E25: =Budget!E23 | F25: =Budget!F23 | G25: =Budget!G23 | H25: =Budget!H23 | I25: =Budget!I23 | ... M25: =Budget!M23
A26: Software, tools & IT | B26: =Budget!B24 | C26: =Budget!C24 | D26: =Budget!D24 | E26: =Budget!E24 | F26: =Budget!F24 | G26: =Budget!G24 | H26: =Budget!H24 | I26: =Budget!I24 | ... M26: =Budget!M24
A27: Verzekeringen | B27: =Budget!B25 | C27: =Budget!C25 | D27: =Budget!D25 | E27: =Budget!E25 | F27: =Budget!F25 | G27: =Budget!G25 | H27: =Budget!H25 | I27: =Budget!I25 | ... M27: =Budget!M25
A28: Onvoorzien | B28: =Budget!B26 | C28: =Budget!C26 | D28: =Budget!D26 | E28: =Budget!E26 | F28: =Budget!F26 | G28: =Budget!G26 | H28: =Budget!H26 | I28: =Budget!I26 | ... M28: =Budget!M26
A29: TOTALE UITGAVEN | B29: =SUM(B19:B28) | C29: =SUM(C19:C28) | D29: =SUM(D19:D28) | E29: =SUM(E19:E28) | F29: =SUM(F19:F28) | G29: =SUM(G19:G28) | H29: =SUM(H19:H28) | I29: =SUM(I19:I28) | ... M29: =SUM(M19:M28)
A31: BTW (21%)
A32: BTW op verkopen (te ontvangen) | B32: =0.21*B16 | C32: =0.21*C16 | D32: =0.21*D16 | E32: =0.21*E16 | F32: =0.21*F16 | G32: =0.21*G16 | H32: =0.21*H16 | I32: =0.21*I16 | ... M32: =0.21*M16
A33: BTW op inkopen (terug te vragen) | B33: =0.21*(B19+B20+B21+B22) | C33: =0.21*(C19+C20+C21+C22) | D33: =0.21*(D19+D20+D21+D22) | E33: =0.21*(E19+E20+E21+E22) | F33: =0.21*(F19+F20+F21+F22) | G33: =0.21*(G19+G20+G21+G22) | H33: =0.21*(H19+H20+H21+H22) | I33: =0.21*(I19+I20+I21+I22) | ... M33: =0.21*(M19+M20+M21+M22)
A34: BTW saldo (af te dragen) | B34: =B32-B33 | C34: =C32-C33 | D34: =D32-D33 | E34: =E32-E33 | F34: =F32-F33 | G34: =G32-G33 | H34: =H32-H33 | I34: =I32-I33 | ... M34: =M32-M33
A36: NETTO CASHFLOW | B36: =B16-B29-B34 | C36: =C16-C29-C34 | D36: =D16-D29-D34 | E36: =E16-E29-E34 | F36: =F16-F29-F34 | G36: =G16-G29-G34 | H36: =H16-H29-H34 | I36: =I16-I29-I34 | ... M36: =M16-M29-M34
A37: Cumulatieve cashflow | B37: =B4+B36 | C37: =B37+C36 | D37: =C37+D36 | E37: =D37+E36 | F37: =E37+F36 | G37: =F37+G36 | H37: =G37+H36 | I37: =H37+I36 | J37: =I37+J36 | ... M37: =L37+M36
A38: Kaspositie einde maand | B38: =B37 | C38: =C37 | D38: =D37 | E38: =E37 | F38: =F37 | G38: =G37 | H38: =H37 | I38: =I37 | ... M38: =M37
A41: Toelichting
A42: Startkapitaal (B4): vul jullie eigen startbedrag in
A43: Inkomsten komen uit Verkoopprognose en Budget sheets
A44: Uitgaven komen uit de Kostensectie van Budget
A45: BTW: 21% over hardware-verkopen minus BTW op inkopen
A46: Kaspositie = startkapitaal + cumulatieve cashflow
A47: Negatieve bedragen worden rood weergegeven
